File: Cu-1.csv
Position (mm),Force (N),Strain (%),Stress (N/mmï¿½),Time (sec)
0.0,0.0,0.0,0.0,0.0
0.014,205,0.056,7.25,1.047
0.031,277,0.124,9.79,2.05
0.048,333,0.192,11.79,3.05
0.064,392,0.256,13.85,4.05
0.081,450,0.324,15.92,5.05
0.097,505,0.388,17.86,6.05
0.114,562,0.456,19.86,7.05
0.131,612,0.524,21.6,8.05
0.148,667,0.592,23.6,9.05
0.164,718,0.656,25.4,10.05
0.181,770,0.724,27.2,11.05
0.198,823,0.792,29.1,12.05
0.214,872,0.856,30.8,13.05
0.231,925,0.924,32.7,14.05
0.248,975,0.992,34.5,15.05
0.264,1022,1.056,36.1,16.05
0.281,1072,1.124,37.9,17.05
0.298,1118,1.192,39.6,18.05
0.314,1165,1.256,41.2,19.05
0.331,1213,1.324,42.9,20
0.347,1257,1.388,44.4,21
0.364,1303,1.456,46.1,22
0.381,1347,1.524,47.6,23
0.397,1390,1.588,49.2,24
0.414,1433,1.656,50.7,25
0.431,1472,1.724,52,26
0.448,1510,1.792,53.4,27
0.464,1547,1.856,54.7,28
0.481,1582,1.924,55.9,29
0.498,1615,1.992,57.1,30
0.514,1645,2.06,58.2,31
0.531,1675,2.12,59.2,32
0.548,1702,2.19,60.2,33
0.564,1727,2.26,61.1,34
0.581,1753,2.32,62,35
0.598,1775,2.39,62.8,36
0.614,1798,2.46,63.6,37
0.631,1820,2.52,64.4,38
0.647,1838,2.59,65,39
0.664,1858,2.66,65.7,40
0.681,1877,2.72,66.4,41
0.697,1893,2.79,67,42
0.714,1910,2.86,67.6,43
0.731,1927,2.92,68.1,44
0.747,1940,2.99,68.6,45
0.764,1958,3.06,69.3,46
0.781,1972,3.12,69.7,47
0.798,1987,3.19,70.3,48
0.814,2000,3.26,70.9,49
0.831,2020,3.32,71.3,50
0.848,2030,3.39,71.8,51
0.864,2040,3.46,72.3,52
0.881,2060,3.52,72.7,53
0.898,2070,3.59,73.2,54
0.914,2080,3.66,73.6,55
0.931,2100,3.72,74.1,56
0.948,2110,3.79,74.5,57
0.964,2120,3.86,74.9,58
0.981,2130,3.92,75.3,59
0.998,2140,3.99,75.7,60
1.014,2150,4.06,76.1,61
1.031,2170,4.12,76.7,62
1.048,2180,4.19,77,63
1.064,2190,4.26,77.4,64
1.081,2200,4.32,77.8,65
1.097,2210,4.39,78.2,66
1.114,2220,4.46,78.6,67
1.131,2230,4.52,78.9,68
1.147,2240,4.59,79.3,69
1.164,2250,4.66,79.7,70
1.181,2260,4.72,80,71
1.197,2270,4.79,80.4,72
1.214,2280,4.86,80.8,73
1.231,2290,4.92,81.1,74
1.248,2300,4.99,81.5,75
1.264,2310,5.06,81.8,76
1.281,2320,5.12,82.1,77
1.298,2330,5.19,82.5,78
1.314,2340,5.26,82.8,79
1.331,2350,5.32,83.2,80
1.348,2360,5.39,83.5,81
1.364,2370,5.46,83.8,82
1.381,2380,5.52,84.2,83
1.398,2390,5.59,84.5,84
1.414,2400,5.66,84.8,85
1.431,2410,5.72,85.2,86
1.447,2420,5.79,85.4,87
1.464,2420,5.86,85.8,88
1.481,2440,5.92,86.1,89
1.497,2440,5.99,86.4,90
1.514,2450,6.06,86.8,91
1.531,2460,6.12,87,92
1.547,2470,6.19,87.3,93
1.564,2480,6.26,87.7,94
1.581,2490,6.32,87.9,95
1.598,2500,6.39,88.2,96
1.614,2500,6.46,88.5,97
1.631,2510,6.52,88.8,98
1.648,2520,6.59,89.1,99
1.664,2530,6.66,89.4,100
1.681,2540,6.72,89.7,101
1.698,2540,6.79,90,102
1.714,2550,6.86,90.3,103
1.731,2560,6.92,90.6,104
1.748,2570,6.99,90.8,105
1.764,2580,7.06,91.2,106
1.781,2590,7.12,91.5,107
1.797,2600,7.19,91.8,108
1.814,2600,7.26,92.1,109
1.831,2610,7.32,92.4,110
1.848,2620,7.39,92.7,111
1.864,2630,7.46,93,112
1.881,2630,7.52,93.1,113
1.898,2640,7.59,93.5,114
1.914,2650,7.66,93.7,115
1.931,2660,7.72,94,116
1.948,2670,7.79,94.3,117
1.964,2680,7.86,94.6,118
1.981,2680,7.92,94.8,119
1.998,2690,7.99,95.2,120
2.01,2700,8.06,95.4,121
2.03,2710,8.12,95.7,122
2.05,2710,8.19,96,123
2.06,2720,8.26,96.2,124
2.08,2730,8.32,96.6,125
2.1,2740,8.39,96.7,126
2.11,2740,8.46,97,127
2.13,2750,8.52,97.3,128
2.15,2760,8.59,97.6,129
2.16,2770,8.66,97.9,130
2.18,2770,8.72,98.1,131
2.2,2780,8.79,98.3,132
2.21,2790,8.86,98.6,133
2.23,2800,8.92,98.9,134
2.25,2800,8.99,99.2,135
2.26,2810,9.06,99.4,136
2.28,2820,9.12,99.7,137
2.3,2830,9.19,100,138
2.31,2830,9.26,100.1,139
2.33,2840,9.32,100.4,140
2.35,2850,9.39,100.7,141
2.36,2850,9.46,100.9,142
2.38,2860,9.52,101.3,143
2.4,2870,9.59,101.4,144
2.41,2880,9.66,101.7,145
2.43,2880,9.72,102,146
2.45,2890,9.79,102.2,147
2.46,2900,9.86,102.5,148
2.48,2900,9.92,102.7,149
2.5,2910,9.99,102.9,150
2.51,2920,10.06,103.2,151
2.53,2920,10.12,103.5,152
2.55,2930,10.19,103.7,153
2.56,2940,10.26,104,154
2.58,2950,10.32,104.2,155
2.6,2950,10.39,104.5,156
2.61,2960,10.46,104.7,157
2.63,2970,10.52,104.9,158
2.65,2980,10.59,105.2,159
2.66,2980,10.66,105.4,160
2.68,2990,10.72,105.6,161
2.7,3000,10.79,105.9,162
2.71,3000,10.86,106.1,163
2.73,3010,10.92,106.4,164
2.75,3020,10.99,106.6,165
2.76,3020,11.06,106.9,166
2.78,3030,11.12,107.2,167
2.8,3040,11.19,107.3,168
2.81,3040,11.26,107.6,169
2.83,3050,11.32,107.9,170
2.85,3060,11.39,108,171
2.86,3060,11.46,108.3,172
2.88,3070,11.52,108.5,173
2.9,3080,11.59,108.8,174
2.91,3080,11.66,109.1,175
2.93,3090,11.72,109.2,176
2.95,3100,11.79,109.5,177
2.96,3100,11.86,109.8,178
2.98,3110,11.92,109.9,179
3,3120,11.99,110.2,180
3.01,3120,12.06,110.4,181
3.03,3130,12.12,110.6,182
3.05,3140,12.19,110.9,183
3.06,3140,12.26,111.1,184
3.08,3150,12.32,111.3,185
3.1,3160,12.39,111.6,186
3.11,3160,12.46,111.8,187
3.13,3170,12.52,112,188
3.15,3170,12.59,112.2,189
3.16,3180,12.66,112.5,190
3.18,3190,12.72,112.7,191
3.2,3190,12.79,112.8,192
3.21,3200,12.86,113.1,193
3.23,3200,12.92,113.3,194
3.25,3210,12.99,113.5,195
3.26,3220,13.06,113.8,196
3.28,3220,13.12,113.9,197
3.3,3230,13.19,114.2,198
3.31,3240,13.26,114.5,199
3.33,3240,13.32,114.6,200
3.35,3250,13.39,114.9,201
3.36,3250,13.46,115.1,202
3.38,3260,13.52,115.2,203
3.4,3270,13.59,115.5,204
3.41,3270,13.66,115.7,205
3.43,3280,13.72,115.9,206
3.45,3280,13.79,116.2,207
3.46,3290,13.86,116.4,208
3.48,3300,13.92,116.6,209
3.5,3300,13.99,116.8,210
3.51,3310,14.06,116.9,211
3.53,3320,14.12,117.2,212
3.55,3320,14.19,117.4,213
3.56,3320,14.26,117.6,214
3.58,3330,14.32,117.8,215
3.6,3340,14.39,118,216
3.61,3340,14.46,118.2,217
3.63,3350,14.52,118.4,218
3.65,3360,14.59,118.7,219
3.66,3360,14.66,118.9,220
3.68,3360,14.72,119,221
3.7,3370,14.79,119.2,222
3.71,3380,14.86,119.5,223
3.73,3380,14.92,119.7,224
3.75,3390,14.99,119.9,225
3.76,3400,15.06,120.1,226
3.78,3400,15.12,120.3,227
3.8,3410,15.19,120.5,228
3.81,3410,15.26,120.7,229
3.83,3420,15.32,120.9,230
3.85,3420,15.39,121.1,231
3.86,3430,15.46,121.3,232
3.88,3440,15.52,121.5,233
3.9,3440,15.59,121.7,234
3.91,3450,15.66,121.9,235
3.93,3450,15.72,122.1,236
3.95,3460,15.79,122.3,237
3.96,3460,15.86,122.5,238
3.98,3470,15.92,122.7,239
4,3480,15.99,122.9,240
4.01,3480,16.06,123.1,241
4.03,3480,16.12,123.3,242
4.05,3490,16.19,123.5,243
4.06,3500,16.26,123.7,244
4.08,3500,16.32,123.8,245
4.1,3510,16.39,124.1,246
4.11,3510,16.46,124.3,247
4.13,3520,16.52,124.5,248
4.15,3520,16.59,124.7,249
4.16,3530,16.66,124.8,250
4.18,3540,16.72,125.1,251
4.2,3540,16.79,125.2,252
4.21,3550,16.86,125.4,253
4.23,3550,16.92,125.7,254
4.25,3560,16.99,125.8,255
4.26,3560,17.06,126,256
4.28,3570,17.12,126.2,257
4.3,3570,17.19,126.3,258
4.31,3580,17.26,126.6,259
4.33,3580,17.32,126.7,260
4.35,3590,17.39,126.9,261
4.36,3600,17.46,127.1,262
4.38,3600,17.52,127.3,263
4.4,3600,17.59,127.4,264
4.41,3610,17.66,127.6,265
4.43,3610,17.72,127.7,266
4.45,3620,17.79,128,267
4.46,3620,17.86,128.1,268
4.48,3630,17.92,128.3,269
4.5,3640,17.99,128.6,270
4.51,3640,18.06,128.7,271
4.53,3640,18.12,128.9,272
4.55,3650,18.19,129.1,273
4.56,3650,18.26,129.2,274
4.58,3660,18.32,129.4,275
4.6,3660,18.39,129.6,276
4.61,3670,18.46,129.8,277
4.63,3680,18.52,130,278
4.65,3680,18.59,130.1,279
4.66,3680,18.66,130.3,280
4.68,3690,18.72,130.5,281
4.7,3690,18.79,130.6,282
4.71,3700,18.86,130.9,283
4.73,3700,18.92,131,284
4.75,3710,18.99,131.2,285
4.76,3720,19.06,131.5,286
4.78,3720,19.12,131.6,287
4.8,3720,19.19,131.7,288
4.81,3730,19.26,131.9,289
4.83,3730,19.32,132,290
4.85,3740,19.39,132.3,291
4.86,3740,19.46,132.4,292
4.88,3750,19.52,132.6,293
4.9,3750,19.59,132.7,294
4.91,3760,19.66,132.9,295
4.93,3760,19.72,133.1,296
4.95,3770,19.79,133.3,297
4.96,3770,19.86,133.4,298
4.98,3780,19.92,133.6,299
5,3780,19.99,133.7,300
5.01,3790,20.1,133.9,301
5.03,3790,20.1,134.1,302
5.05,3800,20.2,134.2,303
5.06,3800,20.3,134.5,304
5.08,3810,20.3,134.6,305
5.1,3810,20.4,134.7,306
5.11,3820,20.5,134.9,307
5.13,3820,20.5,135,308
5.15,3820,20.6,135.2,309
5.16,3830,20.7,135.4,310
5.18,3830,20.7,135.5,311
5.2,3840,20.8,135.7,312
5.21,3840,20.9,135.9,313
5.23,3840,20.9,136,314
5.25,3850,21,136.2,315
5.26,3850,21.1,136.3,316
5.28,3860,21.1,136.5,317
5.3,3860,21.2,136.6,318
5.31,3870,21.3,136.8,319
5.33,3880,21.3,137,320
5.35,3880,21.4,137.2,321
5.36,3880,21.5,137.3,322
5.38,3890,21.5,137.5,323
5.4,3890,21.6,137.6,324
5.41,3900,21.7,137.8,325
5.43,3900,21.7,137.9,326
5.45,3900,21.8,138.1,327
5.46,3910,21.9,138.3,328
5.48,3910,21.9,138.4,329
5.5,3920,22,138.6,330
5.51,3920,22.1,138.8,331
5.53,3930,22.1,138.9,332
5.55,3930,22.2,139.1,333
5.56,3940,22.3,139.2,334
5.58,3940,22.3,139.3,335
5.6,3950,22.4,139.6,336
5.61,3950,22.5,139.6,337
5.63,3950,22.5,139.8,338
5.65,3960,22.6,140,339
5.66,3960,22.7,140.1,340
5.68,3970,22.7,140.3,341
5.7,3970,22.8,140.5,342
5.71,3980,22.9,140.6,343
5.73,3980,22.9,140.8,344
5.75,3980,23,140.9,345
5.76,3990,23.1,141.1,346
5.78,3990,23.1,141.2,347
5.8,4000,23.2,141.3,348
5.81,4000,23.3,141.5,349
5.83,4000,23.3,141.6,350
5.85,4010,23.4,141.7,351
5.86,4010,23.5,141.9,352
5.88,4020,23.5,142.1,353
5.9,4020,23.6,142.2,354
5.91,4020,23.7,142.4,355
5.93,4030,23.7,142.5,356
5.95,4030,23.8,142.6,357
5.96,4040,23.9,142.8,358
5.98,4040,23.9,142.9,359
6,4040,24,143.1,360
6.01,4050,24.1,143.2,361
6.03,4050,24.1,143.3,362
6.05,4060,24.2,143.5,363
6.06,4060,24.3,143.6,364
6.08,4060,24.3,143.7,365
6.1,4070,24.4,143.9,366
6.11,4070,24.5,144,367
6.13,4080,24.5,144.2,368
6.15,4080,24.6,144.4,369
6.16,4080,24.7,144.5,370
6.18,4090,24.7,144.7,371
6.2,4090,24.8,144.8,372
6.21,4100,24.9,144.9,373
6.23,4100,24.9,145.1,374
6.25,4100,25,145.2,375
6.26,4110,25.1,145.3,376
6.28,4110,25.1,145.5,377
6.3,4120,25.2,145.5,378
6.31,4120,25.3,145.7,379
6.33,4120,25.3,145.9,380
6.35,4130,25.4,146,381
6.36,4130,25.5,146.1,382
6.38,4140,25.5,146.2,383
6.4,4140,25.6,146.4,384
6.41,4140,25.7,146.5,385
6.43,4150,25.7,146.7,386
6.45,4150,25.8,146.8,387
6.46,4160,25.9,147,388
6.48,4160,25.9,147.1,389
6.5,4160,26,147.2,390
6.51,4160,26.1,147.3,391
6.53,4170,26.1,147.5,392
6.55,4170,26.2,147.6,393
6.56,4180,26.3,147.7,394
6.58,4180,26.3,147.9,395
6.6,4180,26.4,148,396
6.61,4190,26.5,148.1,397
6.63,4190,26.5,148.2,398
6.65,4200,26.6,148.4,399
6.66,4200,26.7,148.5,400
6.68,4200,26.7,148.7,401
6.7,4200,26.8,148.7,402
6.71,4210,26.9,149,403
6.73,4210,26.9,149,404
6.75,4220,27,149.1,405
6.76,4220,27.1,149.3,406
6.78,4220,27.1,149.4,407
6.8,4230,27.2,149.5,408
6.81,4230,27.3,149.7,409
6.83,4230,27.3,149.7,410
6.85,4240,27.4,150,411
6.86,4240,27.5,150.1,412
6.88,4240,27.5,150.1,413
6.9,4250,27.6,150.3,414
6.91,4250,27.7,150.4,415
6.93,4260,27.7,150.5,416
6.95,4260,27.8,150.7,417
6.96,4260,27.9,150.8,418
6.98,4270,27.9,151,419
7,4270,28,151,420
7.01,4280,28.1,151.2,421
7.03,4280,28.1,151.3,422
7.05,4280,28.2,151.3,423
7.06,4280,28.3,151.5,424
7.08,4290,28.3,151.6,425
7.1,4290,28.4,151.7,426
7.11,4300,28.5,152,427
7.13,4300,28.5,152,428
7.15,4300,28.6,152.2,429
7.16,4300,28.7,152.3,430
7.18,4310,28.7,152.4,431
7.2,4320,28.8,152.6,432
7.21,4320,28.9,152.7,433
7.23,4320,28.9,152.8,434
7.25,4320,29,153,435
7.26,4320,29.1,153,436
7.28,4330,29.1,153.1,437
7.3,4330,29.2,153.3,438
7.31,4340,29.3,153.3,439
7.33,4340,29.3,153.5,440
7.35,4340,29.4,153.6,441
7.36,4350,29.5,153.7,442
7.38,4350,29.5,153.8,443
7.4,4350,29.6,153.9,444
7.41,4360,29.7,154.1,445
7.43,4360,29.7,154.1,446
7.45,4360,29.8,154.3,447
7.46,4370,29.9,154.4,448
7.48,4370,29.9,154.5,449
7.5,4370,30,154.6,450
7.51,4380,30.1,154.7,451
7.53,4380,30.1,154.8,452
7.55,4380,30.2,155,453
7.56,4380,30.3,155.1,454
7.58,4390,30.3,155.2,455
7.6,4390,30.4,155.3,456
7.61,4390,30.5,155.4,457
7.63,4400,30.5,155.6,458
7.65,4400,30.6,155.7,459
7.66,4400,30.7,155.8,460
7.68,4410,30.7,155.9,461
7.7,4410,30.8,156,462
7.71,4410,30.9,156.1,463
7.73,4420,30.9,156.2,464
7.75,4420,31,156.3,465
7.76,4420,31.1,156.4,466
7.78,4430,31.1,156.6,467
7.8,4430,31.2,156.6,468
7.81,4430,31.3,156.8,469
7.83,4430,31.3,156.8,470
7.85,4440,31.4,157,471
7.86,4440,31.5,157.1,472
7.88,4440,31.5,157.2,473
7.9,4450,31.6,157.3,474
7.91,4450,31.7,157.3,475
7.93,4450,31.7,157.4,476
7.95,4460,31.8,157.6,477
7.96,4460,31.9,157.7,478
7.98,4460,31.9,157.8,479
8,4470,32,158,480
8.01,4470,32.1,158,481
8.03,4470,32.1,158.2,482
8.05,4470,32.2,158.2,483
8.06,4480,32.3,158.3,484
8.08,4480,32.3,158.4,485
8.1,4480,32.4,158.5,486
8.11,4490,32.5,158.7,487
8.13,4490,32.5,158.7,488
8.15,4490,32.6,158.8,489
8.16,4500,32.7,159,490
8.18,4500,32.7,159,491
8.2,4500,32.8,159.2,492
8.21,4500,32.9,159.3,493
8.23,4500,32.9,159.3,494
8.25,4510,33,159.5,495
8.26,4510,33.1,159.6,496
8.28,4520,33.1,159.7,497
8.3,4520,33.2,159.8,498
8.31,4520,33.3,159.9,499
8.33,4520,33.3,160,500
8.35,4530,33.4,160.1,501
8.36,4530,33.5,160.2,502
8.38,4530,33.5,160.3,503
8.4,4540,33.6,160.4,504
8.41,4540,33.7,160.5,505
8.43,4540,33.7,160.6,506
8.45,4540,33.8,160.6,507
8.46,4540,33.9,160.7,508
8.48,4550,33.9,160.9,509
8.5,4550,34,161,510
8.51,4560,34.1,161.1,511
8.53,4560,34.1,161.2,512
8.55,4560,34.2,161.2,513
8.56,4560,34.3,161.5,514
8.58,4560,34.3,161.5,515
8.6,4570,34.4,161.6,516
8.61,4570,34.5,161.7,517
8.63,4570,34.5,161.7,518
8.65,4580,34.6,161.9,519
8.66,4580,34.7,161.9,520
8.68,4580,34.7,162,521
8.7,4580,34.8,162.2,522
8.71,4590,34.9,162.2,523
8.73,4590,34.9,162.3,524
8.75,4590,35,162.5,525
8.76,4600,35.1,162.5,526
8.78,4600,35.1,162.6,527
8.8,4600,35.2,162.7,528
8.81,4600,35.3,162.8,529
8.83,4610,35.3,162.9,530
8.85,4610,35.4,163,531
8.86,4610,35.5,163.1,532
8.88,4610,35.5,163.2,533
8.9,4620,35.6,163.3,534
8.91,4620,35.7,163.4,535
8.93,4620,35.7,163.5,536
8.95,4620,35.8,163.6,537
8.96,4630,35.9,163.6,538
8.98,4630,35.9,163.7,539
9,4630,36,163.9,540
9.01,4630,36.1,163.9,541
9.03,4640,36.1,164,542
9.05,4640,36.2,164.1,543
9.06,4640,36.3,164.1,544
9.08,4640,36.3,164.2,545
9.1,4650,36.4,164.3,546
9.11,4650,36.5,164.4,547
9.13,4650,36.5,164.5,548
9.15,4660,36.6,164.6,549
9.16,4660,36.7,164.7,550
9.18,4660,36.7,164.8,551
9.2,4660,36.8,164.9,552
9.21,4660,36.9,165,553
9.23,4670,36.9,165,554
9.25,4670,37,165.1,555
9.26,4670,37.1,165.2,556
9.28,4670,37.1,165.3,557
9.3,4680,37.2,165.4,558
9.31,4680,37.3,165.5,559
9.33,4680,37.3,165.5,560
9.35,4680,37.4,165.7,561
9.36,4690,37.5,165.8,562
9.38,4690,37.5,165.8,563
9.4,4690,37.6,165.9,564
9.41,4690,37.7,165.9,565
9.43,4700,37.7,166.1,566
9.45,4700,37.8,166.2,567
9.46,4700,37.9,166.2,568
9.48,4700,37.9,166.3,569
9.5,4700,38,166.3,570
9.51,4710,38.1,166.5,571
9.53,4710,38.1,166.6,572
9.55,4710,38.2,166.6,573
9.56,4710,38.3,166.7,574
9.58,4720,38.3,166.8,575
9.6,4720,38.4,166.9,576
9.61,4720,38.5,167.1,577
9.63,4720,38.5,167.1,578
9.65,4730,38.6,167.2,579
9.66,4730,38.7,167.3,580
9.68,4730,38.7,167.3,581
9.7,4740,38.8,167.5,582
9.71,4740,38.9,167.5,583
9.73,4740,38.9,167.6,584
9.75,4740,39,167.7,585
9.76,4740,39.1,167.7,586
9.78,4750,39.1,167.9,587
9.8,4750,39.2,167.9,588
9.81,4750,39.3,167.9,589
9.83,4750,39.3,168.1,590
9.85,4760,39.4,168.2,591
9.86,4760,39.5,168.2,592
9.88,4760,39.5,168.4,593
9.9,4760,39.6,168.4,594
9.91,4760,39.7,168.5,595
9.93,4760,39.7,168.5,596
9.95,4770,39.8,168.6,597
9.96,4770,39.9,168.7,598
9.98,4770,39.9,168.8,599
10,4770,40,168.8,600
10.01,4780,40.1,169,601
10.03,4780,40.1,168.9,602
10.05,4780,40.2,169.1,603
10.06,4780,40.3,169.1,604
10.08,4780,40.3,169.2,605
10.1,4790,40.4,169.4,606
10.11,4790,40.5,169.4,607
10.13,4790,40.5,169.5,608
10.15,4800,40.6,169.6,609
10.16,4800,40.7,169.6,610
10.18,4800,40.7,169.7,611
10.2,4800,40.8,169.8,612
10.21,4800,40.9,169.8,613
10.23,4800,40.9,169.9,614
10.25,4800,41,169.9,615
10.26,4810,41.1,170.1,616
10.28,4810,41.1,170.2,617
10.3,4810,41.2,170.2,618
10.31,4820,41.3,170.3,619
10.33,4820,41.3,170.4,620
10.35,4820,41.4,170.4,621
10.36,4820,41.5,170.5,622
10.38,4820,41.5,170.5,623
10.4,4820,41.6,170.6,624
10.41,4830,41.7,170.8,625
10.43,4830,41.7,170.8,626
10.45,4830,41.8,170.9,627
10.46,4830,41.9,170.9,628
10.48,4840,41.9,171,629
10.5,4840,42,171.1,630
10.51,4840,42.1,171.2,631
10.53,4840,42.1,171.2,632
10.55,4840,42.2,171.4,633
10.56,4840,42.3,171.4,634
10.58,4850,42.3,171.5,635
10.6,4850,42.4,171.5,636
10.61,4850,42.5,171.5,637
10.63,4850,42.5,171.7,638
10.65,4860,42.6,171.7,639
10.66,4860,42.7,171.8,640
10.68,4860,42.7,171.9,641
10.7,4860,42.8,171.9,642
10.71,4860,42.9,172,643
10.73,4860,42.9,172.1,644
10.75,4870,43,172.1,645
10.76,4870,43.1,172.2,646
10.78,4870,43.1,172.3,647
10.8,4870,43.2,172.4,648
10.81,4880,43.3,172.4,649
10.83,4880,43.3,172.4,650
10.85,4880,43.4,172.5,651
10.86,4880,43.5,172.6,652
10.88,4880,43.5,172.7,653
10.9,4880,43.6,172.8,654
10.91,4890,43.7,172.8,655
10.93,4890,43.7,172.8,656
10.95,4890,43.8,172.9,657
10.96,4890,43.9,172.9,658
10.98,4890,43.9,173.1,659
11,4900,44,173.2,660
11.01,4900,44.1,173.2,661
11.03,4900,44.1,173.3,662
11.05,4900,44.2,173.3,663
11.06,4900,44.3,173.4,664
11.08,4900,44.3,173.5,665
11.1,4900,44.4,173.5,666
11.11,4910,44.5,173.6,667
11.13,4910,44.5,173.7,668
11.15,4910,44.6,173.7,669
11.16,4910,44.7,173.8,670
11.18,4910,44.7,173.8,671
11.2,4920,44.8,173.8,672
11.21,4920,44.9,174,673
11.23,4920,44.9,174,674
11.25,4920,45,174.1,675
11.26,4920,45.1,174.1,676
11.28,4920,45.1,174.2,677
11.3,4930,45.2,174.3,678
11.31,4930,45.3,174.3,679
11.33,4930,45.3,174.4,680
11.35,4930,45.4,174.5,681
11.36,4930,45.5,174.5,682
11.38,4940,45.5,174.6,683
11.4,4940,45.6,174.7,684
11.41,4940,45.7,174.7,685
11.43,4940,45.7,174.8,686
11.45,4940,45.8,174.8,687
11.46,4940,45.9,174.9,688
11.48,4950,45.9,175,689
11.5,4950,46,175,690
11.51,4950,46.1,175.1,691
11.53,4950,46.1,175.1,692
11.55,4950,46.2,175.2,693
11.56,4960,46.3,175.2,694
11.58,4960,46.3,175.2,695
11.6,4960,46.4,175.4,696
11.61,4960,46.5,175.4,697
11.63,4960,46.5,175.4,698
11.65,4960,46.6,175.5,699
11.66,4960,46.7,175.5,700
11.68,4960,46.7,175.6,701
11.7,4970,46.8,175.7,702
11.71,4970,46.9,175.7,703
11.73,4970,46.9,175.8,704
11.75,4970,47,175.9,705
11.76,4970,47.1,175.8,706
11.78,4980,47.1,176,707
11.8,4980,47.2,176,708
11.81,4980,47.3,176.1,709
11.83,4980,47.3,176.2,710
11.85,4980,47.4,176.2,711
11.86,4980,47.5,176.2,712
11.88,4980,47.5,176.3,713
11.9,4980,47.6,176.3,714
11.91,4990,47.7,176.5,715
11.93,4990,47.7,176.4,716
11.95,4990,47.8,176.5,717
11.96,4990,47.9,176.6,718
11.98,5000,47.9,176.7,719
12,5000,48,176.7,720
12.01,5000,48.1,176.7,721
12.03,5000,48.1,176.8,722
12.05,5000,48.2,176.9,723
12.06,5000,48.3,176.9,724
12.08,5000,48.3,177,725
12.1,5000,48.4,177,726
12.11,5010,48.5,177.1,727
12.13,5010,48.5,177.2,728
12.15,5010,48.6,177.2,729
12.16,5010,48.7,177.3,730
12.18,5020,48.7,177.4,731
12.2,5010,48.8,177.3,732
12.21,5020,48.9,177.4,733
12.23,5020,48.9,177.5,734
12.25,5020,49,177.5,735
12.26,5020,49.1,177.6,736
12.28,5020,49.1,177.6,737
12.3,5020,49.2,177.7,738
12.31,5030,49.3,177.8,739
12.33,5020,49.3,177.7,740
12.35,5030,49.4,177.8,741
12.36,5030,49.5,177.9,742
12.38,5030,49.5,177.9,743
12.4,5030,49.6,178,744
12.41,5030,49.7,178,745
12.43,5040,49.7,178.1,746
12.45,5040,49.8,178.1,747
12.46,5040,49.9,178.1,748
12.48,5040,49.9,178.3,749
12.5,5040,50,178.3,750
12.51,5040,50.1,178.3,751
12.53,5040,50.1,178.4,752
12.55,5040,50.2,178.4,753
12.56,5050,50.3,178.5,754
12.58,5050,50.3,178.5,755
12.6,5050,50.4,178.5,756
12.61,5050,50.5,178.7,757
12.63,5050,50.5,178.7,758
12.65,5050,50.6,178.7,759
12.66,5060,50.7,178.8,760
12.68,5060,50.7,178.8,761
12.7,5060,50.8,178.9,762
12.71,5060,50.9,179,763
12.73,5060,50.9,179,764
12.75,5060,51,179.1,765
12.76,5060,51.1,179,766
12.78,5060,51.1,179.1,767
12.8,5070,51.2,179.2,768
12.81,5060,51.3,179.1,769
12.83,5070,51.3,179.3,770
12.85,5070,51.4,179.3,771
12.86,5070,51.5,179.3,772
12.88,5070,51.5,179.4,773
12.9,5070,51.6,179.4,774
12.91,5070,51.7,179.4,775
12.93,5080,51.7,179.5,776
12.95,5080,51.8,179.5,777
12.96,5080,51.9,179.6,778
12.98,5080,51.9,179.6,779
13,5080,52,179.7,780
13.01,5080,52.1,179.8,781
13.03,5080,52.1,179.7,782
13.05,5080,52.2,179.8,783
13.06,5090,52.3,179.9,784
13.08,5090,52.3,179.9,785
13.1,5090,52.4,180,786
13.11,5090,52.5,180,787
13.13,5090,52.5,180,788
13.15,5090,52.6,180.1,789
13.16,5090,52.7,180.1,790
13.18,5100,52.7,180.2,791
13.2,5100,52.8,180.2,792
13.21,5100,52.9,180.2,793
13.23,5100,52.9,180.3,794
13.25,5100,53,180.3,795
13.26,5100,53.1,180.4,796
13.28,5100,53.1,180.4,797
13.3,5100,53.2,180.4,798
13.31,5100,53.3,180.6,799
13.33,5100,53.3,180.6,800
13.35,5110,53.4,180.6,801
13.36,5110,53.5,180.7,802
13.38,5110,53.5,180.7,803
13.4,5110,53.6,180.7,804
13.41,5110,53.7,180.8,805
13.43,5110,53.7,180.8,806
13.45,5110,53.8,180.8,807
13.46,5120,53.9,180.9,808
13.48,5120,53.9,180.9,809
13.5,5120,54,181,810
13.51,5120,54.1,181,811
13.53,5120,54.1,181,812
13.55,5120,54.2,181.1,813
13.56,5120,54.3,181.1,814
13.58,5120,54.3,181.2,815
13.6,5120,54.4,181.2,816
13.61,5120,54.5,181.3,817
13.63,5130,54.5,181.3,818
13.65,5130,54.6,181.3,819
13.66,5130,54.7,181.4,820
13.68,5130,54.7,181.4,821
13.7,5130,54.8,181.4,822
13.71,5130,54.9,181.5,823
13.73,5130,54.9,181.5,824
13.75,5130,55,181.6,825
13.76,5140,55.1,181.6,826
13.78,5140,55.1,181.6,827
13.8,5140,55.2,181.7,828
13.81,5140,55.3,181.7,829
13.83,5140,55.3,181.7,830
13.85,5140,55.4,181.8,831
13.86,5140,55.5,181.8,832
13.88,5140,55.5,181.8,833
13.9,5140,55.6,182,834
13.91,5140,55.7,181.9,835
13.93,5140,55.7,182,836
13.95,5150,55.8,182.1,837
13.96,5150,55.9,182,838
13.98,5150,55.9,182.1,839
14,5150,56,182.1,840
14.01,5150,56.1,182.2,841
14.03,5150,56.1,182.3,842
14.05,5150,56.2,182.3,843
14.06,5160,56.3,182.3,844
14.08,5160,56.3,182.4,845
14.1,5160,56.4,182.3,846
14.11,5160,56.5,182.4,847
14.13,5160,56.5,182.4,848
14.15,5160,56.6,182.5,849
14.16,5160,56.7,182.6,850
14.18,5160,56.7,182.6,851
14.2,5160,56.8,182.6,852
14.21,5160,56.9,182.6,853
14.23,5160,56.9,182.6,854
14.25,5170,57,182.7,855
14.26,5160,57.1,182.7,856
14.28,5170,57.1,182.8,857
14.3,5170,57.2,182.9,858
14.31,5170,57.3,182.9,859
14.33,5170,57.3,182.9,860
14.35,5170,57.4,182.9,861
14.36,5170,57.5,182.9,862
14.38,5170,57.5,183,863
14.4,5170,57.6,183,864
14.41,5180,57.7,183,865
14.43,5180,57.7,183.1,866
14.45,5180,57.8,183,867
14.46,5180,57.9,183.1,868
14.48,5180,57.9,183.1,869
14.5,5180,58,183.1,870
14.51,5180,58.1,183.3,871
14.53,5180,58.1,183.2,872
14.55,5180,58.2,183.3,873
14.56,5180,58.3,183.3,874
14.58,5180,58.3,183.3,875
14.6,5180,58.4,183.4,876
14.61,5190,58.5,183.4,877
14.63,5190,58.5,183.4,878
14.65,5190,58.6,183.5,879
14.66,5190,58.7,183.5,880
14.68,5190,58.7,183.6,881
14.7,5190,58.8,183.6,882
14.71,5190,58.9,183.6,883
14.73,5190,58.9,183.7,884
14.75,5190,59,183.7,885
14.76,5190,59.1,183.7,886
14.78,5200,59.1,183.7,887
14.8,5200,59.2,183.7,888
14.81,5200,59.3,183.8,889
14.83,5200,59.3,183.8,890
14.85,5200,59.4,183.9,891
14.86,5200,59.5,183.9,892
14.88,5200,59.5,183.9,893
14.9,5200,59.6,183.9,894
14.91,5200,59.7,184,895
14.93,5200,59.7,184,896
14.95,5200,59.8,184,897
14.96,5200,59.9,184,898
14.98,5200,59.9,184,899
15,5200,60,184.1,900
15.01,5200,60.1,184.1,901
15.03,5210,60.1,184.1,902
15.05,5210,60.2,184.2,903
15.06,5210,60.3,184.1,904
15.08,5210,60.3,184.3,905
15.1,5210,60.4,184.3,906
15.11,5210,60.5,184.3,907
15.13,5210,60.5,184.4,908
15.15,5210,60.6,184.3,909
15.16,5210,60.7,184.4,910
15.18,5220,60.7,184.5,911
15.2,5210,60.8,184.4,912
15.21,5220,60.9,184.5,913
15.23,5220,60.9,184.5,914
15.25,5220,61,184.6,915
15.26,5220,61.1,184.6,916
15.28,5220,61.1,184.6,917
15.3,5220,61.2,184.7,918
15.31,5220,61.3,184.7,919
15.33,5220,61.3,184.7,920
15.35,5220,61.4,184.7,921
15.36,5220,61.5,184.7,922
15.38,5220,61.5,184.8,923
15.4,5220,61.6,184.8,924
15.41,5220,61.7,184.8,925
15.43,5230,61.7,184.9,926
15.45,5230,61.8,184.9,927
15.46,5230,61.9,184.9,928
15.48,5230,61.9,184.9,929
15.5,5230,62,184.9,930
15.51,5230,62.1,185,931
15.53,5230,62.1,185,932
15.55,5230,62.2,185,933
15.56,5230,62.3,185,934
15.58,5230,62.3,185,935
15.6,5230,62.4,185,936
15.61,5240,62.5,185.2,937
15.63,5240,62.5,185.2,938
15.65,5240,62.6,185.2,939
15.66,5240,62.7,185.2,940
15.68,5240,62.7,185.2,941
15.7,5240,62.8,185.3,942
15.71,5240,62.9,185.3,943
15.73,5240,62.9,185.2,944
15.75,5240,63,185.3,945
15.76,5240,63.1,185.3,946
15.78,5240,63.1,185.3,947
15.8,5240,63.2,185.4,948
15.81,5240,63.3,185.4,949
15.83,5240,63.3,185.4,950
15.85,5240,63.4,185.5,951
15.86,5240,63.5,185.4,952
15.88,5240,63.5,185.5,953
15.9,5240,63.6,185.5,954
15.91,5240,63.7,185.5,955
15.93,5250,63.7,185.6,956
15.95,5250,63.8,185.6,957
15.96,5250,63.9,185.6,958
15.98,5250,63.9,185.7,959
16,5250,64,185.6,960
16.01,5250,64.1,185.7,961
16.03,5250,64.1,185.7,962
16.05,5250,64.2,185.7,963
16.06,5250,64.3,185.7,964
16.08,5250,64.3,185.7,965
16.1,5250,64.4,185.7,966
16.11,5260,64.5,185.9,967
16.13,5250,64.5,185.7,968
16.15,5260,64.6,185.9,969
16.16,5260,64.7,185.9,970
16.18,5260,64.7,185.9,971
16.2,5260,64.8,185.9,972
16.21,5260,64.9,185.9,973
16.23,5260,64.9,185.9,974
16.25,5260,65,186,975
16.26,5260,65.1,185.9,976
16.28,5260,65.1,186,977
16.3,5260,65.2,186,978
16.31,5260,65.3,186,979
16.33,5260,65.3,186.1,980
16.35,5260,65.4,186.1,981
16.36,5260,65.5,186,982
16.38,5260,65.5,186.2,983
16.4,5260,65.6,186.1,984
16.41,5260,65.7,186.2,985
16.43,5260,65.7,186.2,986
16.45,5260,65.8,186.2,987
16.46,5260,65.9,186.2,988
16.48,5260,65.9,186.2,989
16.5,5260,66,186.2,990
16.51,5270,66.1,186.3,991
16.53,5260,66.1,186.2,992
16.55,5270,66.2,186.3,993
16.56,5270,66.3,186.3,994
16.58,5270,66.3,186.3,995
16.6,5270,66.4,186.4,996
16.61,5270,66.5,186.4,997
16.63,5270,66.5,186.4,998
16.65,5270,66.6,186.4,999
16.66,5270,66.7,186.4,1000
16.68,5270,66.7,186.4,1001
16.7,5270,66.8,186.4,1002
16.71,5270,66.9,186.4,1003
16.73,5270,66.9,186.5,1004
16.75,5270,67,186.5,1005
16.76,5270,67.1,186.5,1006
16.78,5280,67.1,186.6,1007
16.8,5270,67.2,186.5,1008
16.81,5280,67.3,186.6,1009
16.83,5280,67.3,186.6,1010
16.85,5280,67.4,186.6,1011
16.86,5280,67.5,186.6,1012
16.88,5280,67.5,186.6,1013
16.9,5280,67.6,186.7,1014
16.91,5280,67.7,186.7,1015
16.93,5280,67.7,186.7,1016
16.95,5280,67.8,186.7,1017
16.96,5280,67.9,186.7,1018
16.98,5280,67.9,186.7,1019
17,5280,68,186.8,1020
17.01,5280,68.1,186.8,1021
17.03,5280,68.1,186.8,1022
17.05,5280,68.2,186.8,1023
17.06,5280,68.3,186.8,1024
17.08,5280,68.3,186.9,1025
17.1,5280,68.4,186.9,1026
17.11,5280,68.5,186.9,1027
17.13,5280,68.5,186.9,1028
17.15,5280,68.6,186.9,1029
17.16,5280,68.7,186.9,1030
17.18,5280,68.7,186.9,1031
17.2,5280,68.8,186.9,1032
17.21,5290,68.9,187,1033
17.23,5280,68.9,186.9,1034
17.25,5290,69,187,1035
17.26,5290,69.1,187,1036
17.28,5290,69.1,187,1037
17.3,5290,69.2,187,1038
17.31,5290,69.3,187,1039
17.33,5290,69.3,187,1040
17.35,5290,69.4,187.1,1041
17.36,5290,69.5,187,1042
17.38,5290,69.5,187.1,1043
17.4,5290,69.6,187.1,1044
17.41,5290,69.7,187.1,1045
17.43,5290,69.7,187.2,1046
17.45,5290,69.8,187.1,1047
17.46,5290,69.9,187.1,1048
17.48,5290,69.9,187.2,1049
17.5,5290,70,187.1,1050
17.51,5290,70.1,187.2,1051
17.53,5290,70.1,187.2,1052
17.55,5290,70.2,187.2,1053
17.56,5290,70.3,187.2,1054
17.58,5290,70.3,187.2,1055
17.6,5290,70.4,187.2,1056
17.61,5300,70.5,187.3,1057
17.63,5290,70.5,187.2,1058
17.65,5300,70.6,187.3,1059
17.66,5300,70.7,187.3,1060
17.68,5300,70.7,187.3,1061
17.7,5300,70.8,187.3,1062
17.71,5300,70.9,187.3,1063
17.73,5300,70.9,187.3,1064
17.75,5300,71,187.3,1065
17.76,5300,71.1,187.3,1066
17.78,5300,71.1,187.4,1067
17.8,5300,71.2,187.3,1068
17.81,5300,71.3,187.3,1069
17.83,5300,71.3,187.4,1070
17.85,5300,71.4,187.4,1071
17.86,5300,71.5,187.4,1072
17.88,5300,71.5,187.4,1073
17.9,5300,71.6,187.4,1074
17.91,5300,71.7,187.4,1075
17.93,5300,71.7,187.4,1076
17.95,5300,71.8,187.4,1077
17.96,5300,71.9,187.5,1078
17.98,5300,71.9,187.4,1079
18,5300,72,187.5,1080
18.01,5300,72.1,187.5,1081
18.03,5300,72.1,187.4,1082
18.05,5300,72.2,187.5,1083
18.06,5300,72.3,187.5,1084
18.08,5300,72.3,187.5,1085
18.1,5300,72.4,187.6,1086
18.11,5300,72.5,187.5,1087
18.13,5300,72.5,187.6,1088
18.15,5300,72.6,187.6,1089
18.16,5300,72.7,187.5,1090
18.18,5300,72.7,187.6,1091
18.2,5300,72.8,187.6,1092
18.21,5300,72.9,187.6,1093
18.23,5300,72.9,187.6,1094
18.25,5300,73,187.6,1095
18.26,5300,73.1,187.6,1096
18.28,5300,73.1,187.6,1097
18.3,5300,73.2,187.6,1098
18.31,5310,73.3,187.7,1099
18.33,5300,73.3,187.6,1100
18.35,5300,73.4,187.6,1101
18.36,5310,73.5,187.7,1102
18.38,5300,73.5,187.6,1103
18.4,5310,73.6,187.7,1104
18.41,5310,73.7,187.7,1105
18.43,5310,73.7,187.7,1106
18.45,5310,73.8,187.7,1107
18.46,5310,73.9,187.7,1108
18.48,5310,73.9,187.7,1109
18.5,5310,74,187.7,1110
18.51,5310,74.1,187.7,1111
18.53,5310,74.1,187.7,1112
18.55,5310,74.2,187.7,1113
18.56,5310,74.3,187.7,1114
18.58,5310,74.3,187.8,1115
18.6,5310,74.4,187.7,1116
18.61,5310,74.5,187.7,1117
18.63,5310,74.5,187.7,1118
18.65,5310,74.6,187.7,1119
18.66,5310,74.7,187.8,1120
18.68,5310,74.7,187.8,1121
18.7,5310,74.8,187.7,1122
18.71,5310,74.9,187.8,1123
18.73,5310,74.9,187.7,1124
18.75,5310,75,187.8,1125
18.76,5310,75.1,187.8,1126
18.78,5310,75.1,187.8,1127
18.8,5310,75.2,187.8,1128
18.81,5310,75.3,187.8,1129
18.83,5310,75.3,187.8,1130
18.85,5310,75.4,187.9,1131
18.86,5310,75.5,187.8,1132
18.88,5310,75.5,187.8,1133
18.9,5310,75.6,187.9,1134
18.91,5310,75.7,187.8,1135
18.93,5310,75.7,187.9,1136
18.95,5310,75.8,187.8,1137
18.96,5310,75.9,187.8,1138
18.98,5310,75.9,187.9,1139
19,5310,76,187.9,1140
19.01,5310,76.1,187.9,1141
19.03,5310,76.1,187.9,1142
19.05,5310,76.2,187.9,1143
19.06,5310,76.3,187.9,1144
19.08,5310,76.3,187.9,1145
19.1,5310,76.4,187.9,1146
19.11,5310,76.5,187.9,1147
19.13,5310,76.5,187.9,1148
19.15,5310,76.6,187.9,1149
19.16,5310,76.7,187.9,1150
19.18,5310,76.7,187.9,1151
19.2,5310,76.8,187.9,1152
19.21,5310,76.9,187.9,1153
19.23,5310,76.9,187.9,1154
19.25,5320,77,188,1155
19.26,5310,77.1,187.9,1156
19.28,5310,77.1,187.9,1157
19.3,5310,77.2,187.9,1158
19.31,5310,77.3,187.9,1159
19.33,5310,77.3,187.9,1160
19.35,5310,77.4,187.9,1161
19.36,5310,77.5,187.9,1162
19.38,5310,77.5,187.9,1163
19.4,5310,77.6,187.9,1164
19.41,5310,77.7,187.9,1165
19.43,5310,77.7,187.9,1166
19.45,5310,77.8,187.9,1167
19.46,5310,77.9,187.9,1168
19.48,5310,77.9,187.9,1169
19.5,5310,78,187.9,1170
19.51,5320,78.1,188,1171
19.53,5310,78.1,187.9,1172
19.55,5310,78.2,187.9,1173
19.56,5310,78.3,187.9,1174
19.58,5310,78.3,187.9,1175
19.6,5310,78.4,187.9,1176
19.61,5310,78.5,187.9,1177
19.63,5310,78.5,187.9,1178
19.65,5310,78.6,187.9,1179
19.66,5310,78.7,187.9,1180
19.68,5320,78.7,188,1181
19.7,5310,78.8,187.9,1182
19.71,5310,78.9,187.9,1183
19.73,5310,78.9,187.9,1184
19.75,5310,79,187.9,1185
19.76,5320,79.1,188,1186
19.78,5310,79.1,187.9,1187
19.8,5310,79.2,187.9,1188
19.81,5310,79.3,187.9,1189
19.83,5310,79.3,187.9,1190
19.85,5310,79.4,187.9,1191
19.86,5310,79.5,187.9,1192
19.88,5310,79.5,187.9,1193
19.9,5310,79.6,187.9,1194
19.91,5310,79.7,187.9,1195
19.93,5310,79.7,187.9,1196
19.95,5310,79.8,187.9,1197
19.96,5310,79.9,187.9,1198
19.98,5310,79.9,187.9,1199
20,5310,80,187.9,1200
20,5310,80.1,187.9,1201
20,5310,80.1,187.9,1202
20,5310,80.2,187.9,1203
20.1,5310,80.3,187.9,1204
20.1,5310,80.3,187.9,1205
20.1,5310,80.4,187.9,1206
20.1,5310,80.5,187.9,1207
20.1,5310,80.5,187.9,1208
20.1,5310,80.6,187.9,1209
20.2,5310,80.7,187.9,1210
20.2,5310,80.7,187.9,1211
20.2,5310,80.8,187.9,1212
20.2,5310,80.9,187.9,1213
20.2,5310,80.9,187.8,1214
20.2,5310,81,187.9,1215
20.3,5310,81.1,187.8,1216
20.3,5310,81.1,187.8,1217
20.3,5310,81.2,187.9,1218
20.3,5310,81.3,187.7,1219
20.3,5310,81.3,187.8,1220
20.3,5310,81.4,187.8,1221
20.4,5310,81.5,187.7,1222
20.4,5310,81.5,187.8,1223
20.4,5310,81.6,187.7,1224
20.4,5310,81.7,187.7,1225
20.4,5310,81.7,187.8,1226
20.4,5310,81.8,187.7,1227
20.5,5310,81.9,187.7,1228
20.5,5310,81.9,187.7,1229
20.5,5310,82,187.7,1230
20.5,5310,82.1,187.7,1231
20.5,5310,82.1,187.7,1232
20.5,5310,82.2,187.7,1233
20.6,5310,82.3,187.7,1234
20.6,5310,82.3,187.7,1235
20.6,5310,82.4,187.7,1236
20.6,5310,82.5,187.7,1237
20.6,5300,82.5,187.6,1238
20.6,5310,82.6,187.7,1239
20.7,5300,82.7,187.6,1240
20.7,5300,82.7,187.6,1241
20.7,5310,82.8,187.7,1242
20.7,5300,82.9,187.6,1243
20.7,5300,82.9,187.6,1244
20.7,5300,83,187.6,1245
20.8,5300,83.1,187.5,1246
20.8,5300,83.1,187.6,1247
20.8,5300,83.2,187.5,1248
20.8,5300,83.3,187.4,1249
20.8,5300,83.3,187.5,1250
20.8,5300,83.4,187.4,1251
20.9,5300,83.5,187.4,1252
20.9,5300,83.5,187.4,1253
20.9,5300,83.6,187.4,1254
20.9,5300,83.7,187.4,1255
20.9,5300,83.7,187.4,1256
20.9,5300,83.8,187.3,1257
21,5300,83.9,187.3,1258
21,5300,83.9,187.3,1259
21,5300,84,187.3,1260
21,5300,84.1,187.3,1261
21,5290,84.1,187.2,1262
21,5290,84.2,187.2,1263
21.1,5290,84.3,187.2,1264
21.1,5290,84.3,187.1,1265
21.1,5290,84.4,187.2,1266
21.1,5290,84.5,187,1267
21.1,5290,84.5,187,1268
21.1,5290,84.6,187.1,1269
21.2,5290,84.7,187,1270
21.2,5290,84.7,187,1271
21.2,5280,84.8,186.9,1272
21.2,5280,84.9,186.9,1273
21.2,5280,84.9,186.9,1274
21.2,5280,85,186.8,1275
21.3,5280,85.1,186.7,1276
21.3,5280,85.1,186.7,1277
21.3,5280,85.2,186.6,1278
21.3,5280,85.3,186.6,1279
21.3,5280,85.3,186.6,1280
21.3,5270,85.4,186.5,1281
21.4,5270,85.5,186.5,1282
21.4,5270,85.5,186.3,1283
21.4,5270,85.6,186.3,1284
21.4,5270,85.7,186.3,1285
21.4,5260,85.7,186.2,1286
21.4,5260,85.8,186.2,1287
21.5,5260,85.9,186.1,1288
21.5,5260,85.9,186,1289
21.5,5260,86,185.9,1290
21.5,5250,86.1,185.8,1291
21.5,5250,86.1,185.7,1292
21.5,5250,86.2,185.7,1293
21.6,5240,86.3,185.5,1294
21.6,5240,86.3,185.5,1295
21.6,5240,86.4,185.4,1296
21.6,5240,86.5,185.2,1297
21.6,5240,86.5,185.2,1298
21.6,5230,86.6,185,1299
21.7,5230,86.7,184.9,1300
21.7,5230,86.7,184.9,1301
21.7,5220,86.8,184.6,1302
21.7,5220,86.9,184.6,1303
21.7,5210,86.9,184.4,1304
21.7,5210,87,184.2,1305
21.8,5200,87.1,184.1,1306
21.8,5200,87.1,183.9,1307
21.8,5200,87.2,183.9,1308
21.8,5190,87.3,183.7,1309
21.8,5190,87.3,183.4,1310
21.8,5180,87.4,183.3,1311
21.9,5180,87.5,183.1,1312
21.9,5170,87.5,182.9,1313
21.9,5170,87.6,182.8,1314
21.9,5160,87.7,182.6,1315
21.9,5160,87.7,182.4,1316
21.9,5150,87.8,182.2,1317
22,5140,87.9,181.8,1318
22,5140,87.9,181.7,1319
22,5130,88,181.4,1320
22,5120,88.1,181.3,1321
22,5120,88.1,181,1322
22,5110,88.2,180.8,1323
22.1,5110,88.3,180.6,1324
22.1,5100,88.3,180.3,1325
22.1,5090,88.4,180.1,1326
22.1,5080,88.5,179.8,1327
22.1,5080,88.5,179.6,1328
22.1,5070,88.6,179.3,1329
22.2,5060,88.7,179.1,1330
22.2,5050,88.7,178.7,1331
22.2,5050,88.8,178.5,1332
22.2,5040,88.9,178.1,1333
22.2,5030,88.9,177.8,1334
22.2,5020,89,177.6,1335
22.3,5010,89.1,177.3,1336
22.3,5000,89.1,177,1337
22.3,5000,89.2,176.7,1338
22.3,4980,89.3,176.3,1339
22.3,4980,89.3,176,1340
22.3,4970,89.4,175.7,1341
22.4,4960,89.5,175.3,1342
22.4,4950,89.5,175,1343
22.4,4940,89.6,174.6,1344
22.4,4930,89.7,174.2,1345
22.4,4920,89.7,173.9,1346
22.4,4900,89.8,173.5,1347
22.5,4900,89.9,173.1,1348
22.5,4880,89.9,172.7,1349
22.5,4870,90,172.4,1350
22.5,4860,90.1,171.9,1351
22.5,4850,90.1,171.5,1352
22.5,4840,90.2,171.2,1353
22.6,4830,90.3,170.7,1354
22.6,4820,90.3,170.3,1355
22.6,4800,90.4,169.9,1356
22.6,4790,90.5,169.4,1357
22.6,4780,90.5,168.9,1358
22.6,4760,90.6,168.5,1359
22.7,4750,90.7,168,1360
22.7,4740,90.7,167.6,1361
22.7,4720,90.8,167.1,1362
22.7,4710,90.9,166.6,1363
22.7,4700,90.9,166.2,1364
22.7,4680,91,165.6,1365
22.8,4670,91.1,165.1,1366
22.8,4660,91.1,164.6,1367
22.8,4640,91.2,164.1,1368
22.8,4630,91.3,163.6,1369
22.8,4610,91.3,163,1370
22.8,4600,91.4,162.5,1371
22.9,4580,91.5,162,1372
22.9,4560,91.5,161.5,1373
22.9,4550,91.6,160.9,1374
22.9,4530,91.7,160.3,1375
22.9,4520,91.7,159.7,1376
22.9,4500,91.8,159.2,1377
23,4480,91.9,158.6,1378
23,4460,91.9,157.9,1379
23,4450,92,157.4,1380
23,4430,92.1,156.7,1381
23,4420,92.1,156.1,1382
23,4400,92.2,155.5,1383
23.1,4380,92.3,154.8,1384
23.1,4360,92.3,154.1,1385
23.1,4340,92.4,153.5,1386
23.1,4320,92.5,152.8,1387
23.1,4300,92.5,152.1,1388
23.1,4280,92.6,151.4,1389
23.2,4260,92.7,150.7,1390
23.2,4240,92.7,150,1391
23.2,4220,92.8,149.3,1392
23.2,4200,92.9,148.6,1393
23.2,4180,92.9,147.8,1394
23.2,4160,93,147.1,1395
23.3,4140,93.1,146.3,1396
23.3,4110,93.1,145.5,1397
23.3,4090,93.2,144.7,1398
23.3,4070,93.3,143.9,1399
23.3,4050,93.3,143.1,1400
23.3,4020,93.4,142.3,1401
23.4,4000,93.5,141.5,1402
23.4,3980,93.5,140.6,1403
23.4,3950,93.6,139.8,1404
23.4,3920,93.7,138.8,1405
23.4,3900,93.7,138.1,1406
23.4,3880,93.8,137.1,1407
23.5,3850,93.9,136.1,1408
23.5,3820,93.9,135.3,1409
23.5,3800,94,134.3,1410
23.5,3770,94.1,133.3,1411
23.5,3740,94.1,132.3,1412
23.5,3710,94.2,131.3,1413
23.6,3680,94.3,130.3,1414
23.6,3660,94.3,129.3,1415
23.6,3620,94.4,128.2,1416
23.6,3590,94.5,127.1,1417
23.6,3560,94.5,125.8,1418
23.6,3510,94.6,124.3,1419
23.7,3420,94.7,121,1420
23.7,2810,94.7,99.4,1421
23.7,2420,94.8,85.7,1422
23.7,-743,94.9,-26.3,1423
23.7,-743,94.9,-26.3,1424
23.7,-743,95,-26.3,1425
23.8,-742,95.1,-26.2,1426
23.8,-742,95.1,-26.2,1427
23.8,-742,95.2,-26.2,1428
23.8,-742,95.3,-26.2,1429
23.8,-742,95.3,-26.2,1430
23.8,-742,95.4,-26.2,1431
23.9,-742,95.5,-26.2,1432
23.9,-742,95.5,-26.2,1433
23.9,-743,95.6,-26.3,1434
23.9,-742,95.7,-26.2,1435
23.9,-742,95.7,-26.2,1436
23.9,-742,95.8,-26.2,1437
24,-742,95.9,-26.2,1438
24,-742,95.9,-26.2,1439
24,-742,96,-26.2,1440
24,-742,96.1,-26.2,1441
24,-742,96.1,-26.2,1442
24,-742,96.2,-26.2,1443
24.1,-742,96.3,-26.2,1444
24.1,-742,96.3,-26.2,1445
24.1,-742,96.4,-26.2,1446
24.1,-742,96.4,-26.2,1447
*****************************End of Data*****************************