File: FeAlSi-1.csv
"Position (mm)","Force (N)","Strain (%)","Stress (N/mmï¿½)","Time (sec)"
0.0,-5,0.0,-0.278,0.0
0.0,-5,0.0,-0.278,0.1719
0.001,0.0,0.004,0.0,0.297
0.003,25,0.012,1.389,0.422
0.005,60,0.02,3.33,0.547
0.008,95,0.032,5.28,0.672
0.01,126.7,0.04,7.04,0.797
0.012,153.3,0.048,8.52,0.922
0.014,180,0.056,10,1.047
0.016,198.3,0.064,11.02,1.172
0.018,212,0.072,11.76,1.297
0.02,225,0.08,12.5,1.422
0.022,235,0.088,13.06,1.547
0.025,247,0.1,13.7,1.672
0.027,260,0.108,14.44,1.797
0.029,272,0.116,15.09,1.922
0.031,283,0.124,15.74,2.05
0.033,297,0.132,16.48,2.17
0.035,307,0.14,17.04,2.3
0.037,317,0.148,17.59,2.42
0.039,330,0.156,18.33,2.55
0.041,340,0.164,18.89,2.67
0.043,350,0.172,19.44,2.8
0.046,362,0.184,20.1,2.92
0.047,372,0.188,20.6,3.05
0.05,382,0.2,21.2,3.17
0.052,392,0.208,21.8,3.3
0.054,402,0.216,22.3,3.42
0.056,410,0.224,22.8,3.55
0.058,420,0.232,23.3,3.67
0.06,432,0.24,24,3.8
0.062,438,0.248,24.4,3.92
0.064,450,0.256,25,4.05
0.066,458,0.264,25.5,4.17
0.068,467,0.272,25.9,4.3
0.071,477,0.284,26.5,4.42
0.072,485,0.288,26.9,4.55
0.074,493,0.296,27.4,4.67
0.077,505,0.308,28.1,4.8
0.079,515,0.316,28.6,4.92
0.081,522,0.324,29,5.05
0.083,532,0.332,29.5,5.17
0.085,542,0.34,30.1,5.3
0.087,548,0.348,30.5,5.42
0.089,558,0.356,31,5.55
0.091,568,0.364,31.6,5.67
0.093,575,0.372,31.9,5.8
0.095,585,0.38,32.5,5.92
0.098,595,0.392,33.1,6.05
0.099,602,0.396,33.4,6.17
0.102,612,0.408,34,6.3
0.104,622,0.416,34.5,6.42
0.106,628,0.424,34.9,6.55
0.108,638,0.432,35.5,6.67
0.11,650,0.44,36.1,6.8
0.112,655,0.448,36.4,6.92
0.114,665,0.456,36.9,7.05
0.116,675,0.464,37.5,7.17
0.118,682,0.472,37.9,7.3
0.12,690,0.48,38.3,7.42
0.123,702,0.492,39,7.55
0.124,708,0.496,39.4,7.67
0.127,717,0.508,39.8,7.8
0.129,727,0.516,40.4,7.92
0.131,733,0.524,40.7,8.05
0.133,742,0.532,41.2,8.17
0.135,752,0.54,41.8,8.3
0.137,758,0.548,42.1,8.42
0.139,767,0.556,42.6,8.55
0.141,777,0.564,43.1,8.67
0.143,783,0.572,43.5,8.8
0.145,792,0.58,44,8.92
0.148,802,0.592,44.5,9.05
0.149,808,0.596,44.9,9.17
0.152,817,0.608,45.4,9.3
0.154,827,0.616,45.9,9.42
0.156,833,0.624,46.3,9.55
0.158,842,0.632,46.8,9.67
0.16,855,0.64,47.5,9.8
0.162,863,0.648,48,9.92
0.164,868,0.656,48.2,10.05
0.166,878,0.664,48.8,10.17
0.168,887,0.672,49.3,10.3
0.17,893,0.68,49.6,10.42
0.173,905,0.692,50.3,10.55
0.174,913,0.696,50.7,10.67
0.177,922,0.708,51.2,10.8
0.179,932,0.716,51.8,10.92
0.181,940,0.724,52.2,11.05
0.183,948,0.732,52.7,11.17
0.185,958,0.74,53.2,11.3
0.187,967,0.748,53.7,11.42
0.189,975,0.756,54.2,11.55
0.191,985,0.764,54.7,11.67
0.193,995,0.772,55.3,11.8
0.195,1002,0.78,55.6,11.92
0.198,1012,0.792,56.2,12.05
0.2,1022,0.8,56.8,12.17
0.202,1028,0.808,57.1,12.3
0.204,1038,0.816,57.7,12.42
0.206,1048,0.824,58.2,12.55
0.208,1055,0.832,58.6,12.67
0.21,1067,0.84,59.3,12.8
0.212,1077,0.848,59.8,12.92
0.214,1083,0.856,60.2,13.05
0.216,1093,0.864,60.7,13.17
0.218,1103,0.872,61.3,13.3
0.22,1110,0.88,61.7,13.42
0.222,1122,0.888,62.3,13.55
0.225,1132,0.9,62.9,13.67
0.227,1140,0.908,63.3,13.8
0.229,1150,0.916,63.9,13.92
0.231,1160,0.924,64.4,14.05
0.233,1167,0.932,64.8,14.17
0.235,1178,0.94,65.5,14.3
0.237,1188,0.948,66,14.42
0.239,1195,0.956,66.4,14.55
0.241,1203,0.964,66.9,14.67
0.243,1215,0.972,67.5,14.8
0.245,1223,0.98,68,14.92
0.248,1233,0.992,68.5,15.05
0.25,1243,1,69.1,15.17
0.251,1252,1.004,69.5,15.3
0.254,1260,1.016,70,15.42
0.256,1272,1.024,70.6,15.55
0.258,1282,1.032,71.2,15.67
0.26,1290,1.04,71.7,15.8
0.262,1302,1.048,72.3,15.92
0.264,1310,1.056,72.8,16.05
0.266,1318,1.064,73.2,16.17
0.268,1330,1.072,73.9,16.3
0.27,1338,1.08,74.4,16.42
0.272,1347,1.088,74.8,16.55
0.275,1360,1.1,75.6,16.67
0.277,1367,1.108,75.9,16.8
0.279,1377,1.116,76.5,16.92
0.281,1388,1.124,77.1,17.05
0.283,1397,1.132,77.6,17.17
0.285,1405,1.14,78.1,17.3
0.287,1417,1.148,78.7,17.42
0.289,1425,1.156,79.2,17.55
0.291,1433,1.164,79.6,17.67
0.293,1445,1.172,80.3,17.8
0.295,1453,1.18,80.7,17.92
0.298,1462,1.192,81.2,18.05
0.3,1473,1.2,81.9,18.17
0.302,1482,1.208,82.3,18.3
0.304,1490,1.216,82.8,18.42
0.306,1502,1.224,83.4,18.55
0.308,1510,1.232,83.9,18.67
0.31,1518,1.24,84.4,18.8
0.312,1530,1.248,85,18.92
0.314,1538,1.256,85.5,19.05
0.316,1547,1.264,85.9,19.17
0.318,1558,1.272,86.6,19.3
0.32,1568,1.28,87.1,19.42
0.322,1577,1.288,87.6,19.55
0.325,1587,1.3,88.1,19.67
0.327,1597,1.308,88.7,19.8
0.329,1605,1.316,89.2,19.92
0.331,1617,1.324,89.8,20
0.333,1627,1.332,90.4,20.2
0.335,1633,1.34,90.7,20.3
0.337,1645,1.348,91.4,20.4
0.339,1655,1.356,91.9,20.5
0.341,1663,1.364,92.4,20.7
0.343,1675,1.372,93.1,20.8
0.345,1685,1.38,93.6,20.9
0.347,1693,1.388,94.1,21
0.35,1705,1.4,94.7,21.2
0.352,1715,1.408,95.3,21.3
0.354,1723,1.416,95.7,21.4
0.356,1733,1.424,96.3,21.5
0.358,1745,1.432,96.9,21.7
0.36,1753,1.44,97.4,21.8
0.362,1765,1.448,98.1,21.9
0.364,1777,1.456,98.7,22
0.366,1785,1.464,99.2,22.2
0.368,1795,1.472,99.7,22.3
0.37,1805,1.48,100.3,22.4
0.372,1813,1.488,100.7,22.5
0.375,1825,1.5,101.4,22.7
0.377,1835,1.508,101.9,22.8
0.379,1843,1.516,102.4,22.9
0.381,1855,1.524,103.1,23
0.383,1865,1.532,103.6,23.2
0.385,1873,1.54,104.1,23.3
0.387,1885,1.548,104.7,23.4
0.389,1897,1.556,105.4,23.5
0.391,1905,1.564,105.8,23.7
0.393,1915,1.572,106.4,23.8
0.395,1927,1.58,107,23.9
0.397,1935,1.588,107.5,24
0.4,1945,1.6,108.1,24.2
0.402,1957,1.608,108.7,24.3
0.404,1965,1.616,109.2,24.4
0.406,1977,1.624,109.8,24.5
0.408,1988,1.632,110.5,24.7
0.41,1997,1.64,110.9,24.8
0.412,2010,1.648,111.5,24.9
0.414,2020,1.656,112.1,25
0.416,2030,1.664,112.6,25.2
0.418,2040,1.672,113.1,25.3
0.42,2050,1.68,113.8,25.4
0.422,2060,1.688,114.4,25.5
0.425,2070,1.7,114.8,25.7
0.427,2080,1.708,115.6,25.8
0.429,2090,1.716,116.1,25.9
0.431,2100,1.724,116.6,26
0.433,2110,1.732,117.2,26.2
0.435,2120,1.74,117.7,26.3
0.437,2130,1.748,118.2,26.4
0.439,2140,1.756,119,26.5
0.441,2150,1.764,119.5,26.7
0.443,2160,1.772,120.1,26.8
0.445,2170,1.78,120.7,26.9
0.447,2180,1.788,121.3,27
0.449,2190,1.796,121.8,27.2
0.452,2200,1.808,122.5,27.3
0.454,2220,1.816,123.1,27.4
0.456,2220,1.824,123.5,27.5
0.458,2240,1.832,124.3,27.7
0.46,2250,1.84,124.9,27.8
0.462,2260,1.848,125.4,27.9
0.464,2270,1.856,126,28
0.466,2280,1.864,126.6,28.2
0.468,2290,1.872,127,28.3
0.471,2300,1.884,127.7,28.4
0.472,2310,1.888,128.2,28.5
0.474,2320,1.896,128.7,28.7
0.477,2330,1.908,129.4,28.8
0.479,2340,1.916,130,28.9
0.481,2350,1.924,130.5,29
0.483,2360,1.932,131.2,29.2
0.485,2370,1.94,131.8,29.3
0.487,2380,1.948,132.2,29.4
0.489,2390,1.956,132.9,29.5
0.491,2400,1.964,133.5,29.7
0.493,2410,1.972,134.1,29.8
0.495,2420,1.98,134.7,29.9
0.498,2440,1.992,135.3,30
0.5,2440,2,135.8,30.2
0.502,2460,2.01,136.5,30.3
0.504,2470,2.02,137,30.4
0.506,2480,2.02,137.5,30.5
0.508,2490,2.03,138.1,30.7
0.51,2500,2.04,138.8,30.8
0.512,2510,2.05,139.3,30.9
0.514,2520,2.06,139.9,31
0.516,2530,2.06,140.6,31.2
0.518,2540,2.07,141,31.3
0.52,2550,2.08,141.7,31.4
0.522,2560,2.09,142.4,31.5
0.524,2570,2.1,142.9,31.7
0.527,2580,2.11,143.5,31.8
0.529,2600,2.12,144.2,31.9
0.531,2600,2.12,144.6,32
0.533,2620,2.13,145.3,32.2
0.535,2630,2.14,146,32.3
0.537,2640,2.15,146.5,32.4
0.539,2650,2.16,147.1,32.5
0.541,2660,2.16,147.9,32.7
0.543,2670,2.17,148.3,32.8
0.546,2680,2.18,149,32.9
0.548,2690,2.19,149.6,33
0.549,2700,2.2,150.1,33.2
0.552,2710,2.21,150.7,33.3
0.554,2730,2.22,151.5,33.4
0.556,2740,2.22,151.9,33.5
0.558,2740,2.23,152.5,33.7
0.56,2760,2.24,153.2,33.8
0.562,2770,2.25,153.8,33.9
0.564,2780,2.26,154.4,34
0.566,2790,2.26,155.1,34.2
0.568,2800,2.27,155.6,34.3
0.57,2810,2.28,156.1,34.4
0.573,2820,2.29,156.8,34.5
0.574,2830,2.3,157.4,34.7
0.577,2840,2.31,158,34.8
0.579,2860,2.32,158.6,34.9
0.581,2870,2.32,159.3,35
0.583,2880,2.33,159.7,35.2
0.585,2890,2.34,160.5,35.3
0.587,2900,2.35,161,35.4
0.589,2910,2.36,161.6,35.5
0.591,2920,2.36,162.3,35.7
0.593,2930,2.37,162.9,35.8
0.595,2940,2.38,163.4,35.9
0.598,2950,2.39,164.1,36
0.599,2960,2.4,164.7,36.2
0.602,2970,2.41,165.2,36.3
0.604,2990,2.42,166,36.4
0.606,3000,2.42,166.7,36.5
0.608,3010,2.43,167.1,36.7
0.61,3020,2.44,167.9,36.8
0.612,3030,2.45,168.4,36.9
0.614,3040,2.46,169,37
0.616,3050,2.46,169.6,37.2
0.618,3070,2.47,170.4,37.3
0.62,3080,2.48,170.8,37.4
0.623,3090,2.49,171.6,37.5
0.625,3100,2.5,172.2,37.7
0.627,3110,2.51,172.7,37.8
0.629,3120,2.52,173.4,37.9
0.631,3130,2.52,174.1,38
0.633,3140,2.53,174.5,38.2
0.635,3160,2.54,175.3,38.3
0.637,3170,2.55,175.9,38.4
0.639,3180,2.56,176.4,38.5
0.641,3190,2.56,177,38.7
0.643,3200,2.57,177.8,38.8
0.645,3210,2.58,178.3,38.9
0.647,3220,2.59,179,39
0.65,3230,2.6,179.6,39.2
0.652,3240,2.61,180.2,39.3
0.654,3260,2.62,180.8,39.4
0.656,3270,2.62,181.5,39.5
0.658,3280,2.63,182,39.7
0.66,3290,2.64,182.7,39.8
0.662,3300,2.65,183.3,39.9
0.664,3310,2.66,184,40
0.666,3320,2.66,184.6,40.2
0.668,3340,2.67,185.3,40.3
0.67,3340,2.68,185.8,40.4
0.673,3360,2.69,186.4,40.5
0.675,3370,2.7,187.1,40.7
0.676,3380,2.7,187.7,40.8
0.679,3390,2.72,188.3,40.9
0.681,3400,2.72,189,41
0.683,3410,2.73,189.6,41.2
0.685,3420,2.74,190.2,41.3
0.687,3440,2.75,190.9,41.4
0.689,3450,2.76,191.6,41.5
0.691,3460,2.76,192,41.7
0.693,3470,2.77,192.7,41.8
0.695,3480,2.78,193.3,41.9
0.697,3490,2.79,194,42
0.7,3500,2.8,194.7,42.2
0.702,3520,2.81,195.4,42.3
0.704,3530,2.82,195.9,42.4
0.706,3540,2.82,196.7,42.5
0.708,3550,2.83,197.2,42.7
0.71,3560,2.84,197.8,42.8
0.712,3570,2.85,198.5,42.9
0.714,3580,2.86,199.2,43
0.716,3600,2.86,199.7,43.2
0.718,3610,2.87,200,43.3
0.72,3620,2.88,201,43.4
0.722,3630,2.89,202,43.5
0.725,3640,2.9,202,43.7
0.727,3650,2.91,203,43.8
0.729,3660,2.92,204,43.9
0.731,3680,2.92,204,44
0.733,3690,2.93,205,44.2
0.735,3700,2.94,205,44.3
0.737,3710,2.95,206,44.4
0.739,3720,2.96,207,44.5
0.741,3730,2.96,207,44.7
0.743,3750,2.97,208,44.8
0.745,3760,2.98,209,44.9
0.747,3770,2.99,209,45
0.75,3780,3,210,45.2
0.752,3790,3.01,211,45.3
0.754,3800,3.02,211,45.4
0.756,3820,3.02,212,45.5
0.758,3830,3.03,213,45.7
0.76,3840,3.04,213,45.8
0.762,3850,3.05,214,45.9
0.764,3860,3.06,215,46
0.766,3880,3.06,215,46.2
0.768,3890,3.07,216,46.3
0.77,3900,3.08,217,46.4
0.772,3910,3.09,217,46.5
0.775,3920,3.1,218,46.7
0.777,3940,3.11,219,46.8
0.779,3940,3.12,219,46.9
0.781,3960,3.12,220,47
0.783,3970,3.13,221,47.2
0.785,3980,3.14,221,47.3
0.787,3990,3.15,222,47.4
0.789,4000,3.16,222,47.5
0.791,4020,3.16,223,47.7
0.793,4020,3.17,224,47.8
0.795,4040,3.18,224,47.9
0.797,4050,3.19,225,48
0.8,4060,3.2,226,48.2
0.802,4070,3.21,226,48.3
0.804,4080,3.22,227,48.4
0.806,4100,3.22,228,48.5
0.808,4110,3.23,228,48.7
0.81,4120,3.24,229,48.8
0.812,4130,3.25,229,48.9
0.814,4140,3.26,230,49
0.816,4160,3.26,231,49.2
0.818,4170,3.27,231,49.3
0.82,4180,3.28,232,49.4
0.822,4190,3.29,233,49.5
0.825,4200,3.3,233,49.7
0.827,4220,3.31,234,49.8
0.829,4230,3.32,235,49.9
0.831,4240,3.32,235,50
0.833,4250,3.33,236,50.2
0.835,4260,3.34,237,50.3
0.837,4270,3.35,237,50.4
0.839,4280,3.36,238,50.5
0.841,4300,3.36,239,50.7
0.843,4310,3.37,239,50.8
0.845,4320,3.38,240,50.9
0.847,4330,3.39,241,51
0.849,4340,3.4,241,51.2
0.852,4360,3.41,242,51.3
0.854,4370,3.42,243,51.4
0.856,4380,3.42,243,51.5
0.858,4390,3.43,244,51.7
0.86,4400,3.44,245,51.8
0.862,4410,3.45,245,51.9
0.864,4430,3.46,246,52
0.866,4440,3.46,247,52.2
0.868,4450,3.47,247,52.3
0.87,4460,3.48,248,52.4
0.872,4480,3.49,249,52.5
0.874,4480,3.5,249,52.7
0.877,4500,3.51,250,52.8
0.879,4510,3.52,251,52.9
0.881,4520,3.52,251,53
0.883,4530,3.53,252,53.2
0.885,4550,3.54,253,53.3
0.887,4560,3.55,253,53.4
0.889,4570,3.56,254,53.5
0.891,4580,3.56,255,53.7
0.893,4590,3.57,255,53.8
0.895,4600,3.58,256,53.9
0.897,4620,3.59,256,54
0.899,4630,3.6,257,54.2
0.902,4640,3.61,258,54.3
0.904,4650,3.62,259,54.4
0.906,4660,3.62,259,54.5
0.908,4670,3.63,260,54.7
0.91,4690,3.64,260,54.8
0.912,4700,3.65,261,54.9
0.914,4710,3.66,262,55
0.916,4720,3.66,262,55.2
0.918,4740,3.67,263,55.3
0.92,4740,3.68,264,55.4
0.922,4760,3.69,264,55.5
0.924,4770,3.7,265,55.7
0.927,4780,3.71,266,55.8
0.929,4800,3.72,266,55.9
0.931,4810,3.72,267,56
0.933,4820,3.73,268,56.2
0.935,4830,3.74,268,56.3
0.937,4840,3.75,269,56.4
0.939,4850,3.76,270,56.5
0.941,4870,3.76,270,56.7
0.943,4880,3.77,271,56.8
0.945,4890,3.78,271,56.9
0.948,4900,3.79,272,57
0.949,4910,3.8,273,57.2
0.952,4920,3.81,274,57.3
0.954,4940,3.82,274,57.4
0.956,4950,3.82,275,57.5
0.958,4960,3.83,275,57.7
0.96,4970,3.84,276,57.8
0.962,4980,3.85,277,57.9
0.964,4990,3.86,277,58
0.966,5010,3.86,278,58.2
0.968,5020,3.87,279,58.3
0.97,5030,3.88,279,58.4
0.973,5040,3.89,280,58.5
0.975,5060,3.9,281,58.7
0.976,5060,3.9,281,58.8
0.979,5080,3.92,282,58.9
0.981,5090,3.92,283,59
0.983,5100,3.93,283,59.2
0.985,5110,3.94,284,59.3
0.987,5120,3.95,285,59.4
0.989,5140,3.96,285,59.5
0.991,5150,3.96,286,59.7
0.993,5160,3.97,287,59.8
0.995,5170,3.98,287,59.9
0.998,5180,3.99,288,60
1,5200,4,289,60.2
1.002,5210,4.01,289,60.3
1.004,5220,4.02,290,60.4
1.006,5230,4.02,291,60.5
1.008,5240,4.03,291,60.7
1.013,4890,4.05,272,60.8
1.013,363,4.05,20.2,60.9
1.015,-783,4.06,-43.5,61
1.017,-783,4.07,-43.5,61.2
1.019,-783,4.08,-43.5,61.3
1.02,-782,4.08,-43.4,61.4
1.022,-782,4.09,-43.4,61.5
1.025,-780,4.1,-43.3,61.7
1.027,-780,4.11,-43.3,61.8
1.029,-780,4.12,-43.3,61.9
1.031,-778,4.12,-43.2,62
1.033,-778,4.13,-43.2,62.2
1.035,-777,4.14,-43.1,62.3
1.037,-777,4.15,-43.1,62.4
1.039,-777,4.16,-43.1,62.5
1.041,-775,4.16,-43.1,62.7
1.043,-775,4.17,-43.1,62.8
1.045,-775,4.18,-43.1,62.9
1.047,-773,4.19,-43,63
1.05,-773,4.2,-43,63.2
1.052,-773,4.21,-43,63.3
1.054,-773,4.22,-43,63.4
1.056,-773,4.22,-43,63.5
1.058,-772,4.23,-42.9,63.7
1.06,-772,4.24,-42.9,63.8
1.062,-772,4.25,-42.9,63.9
1.064,-772,4.26,-42.9,64
1.066,-770,4.26,-42.8,64.2
1.068,-770,4.27,-42.8,64.3
1.071,-770,4.28,-42.8,64.4
1.072,-770,4.29,-42.8,64.5
1.075,-770,4.3,-42.8,64.7
1.077,-768,4.31,-42.7,64.8
1.079,-768,4.32,-42.7,64.9
1.081,-768,4.32,-42.7,65
1.083,-768,4.33,-42.7,65.2
1.085,-767,4.34,-42.6,65.3
1.087,-768,4.35,-42.7,65.4
1.089,-767,4.36,-42.6,65.5
1.091,-767,4.36,-42.6,65.7
1.093,-767,4.37,-42.6,65.8
1.095,-767,4.38,-42.6,65.9
1.097,-765,4.39,-42.5,66
1.099,-765,4.4,-42.5,66.2
1.102,-765,4.41,-42.5,66.3
1.104,-765,4.42,-42.5,66.4
1.106,-765,4.42,-42.5,66.5
1.108,-765,4.43,-42.5,66.7
1.11,-765,4.44,-42.5,66.8
1.112,-765,4.45,-42.5,66.9
1.114,-765,4.46,-42.5,67
1.116,-763,4.46,-42.4,67.2
1.118,-763,4.47,-42.4,67.3
1.12,-763,4.48,-42.4,67.4
1.122,-763,4.49,-42.4,67.5
1.124,-763,4.5,-42.4,67.7
1.127,-763,4.51,-42.4,67.8
1.129,-763,4.52,-42.4,67.9
1.131,-763,4.52,-42.4,68
1.133,-763,4.53,-42.4,68.2
1.135,-763,4.54,-42.4,68.3
1.137,-763,4.55,-42.4,68.4
1.139,-762,4.56,-42.3,68.5
1.141,-762,4.56,-42.3,68.7
1.143,-762,4.57,-42.3,68.8
1.145,-762,4.58,-42.3,68.9
1.148,-762,4.59,-42.3,69
1.149,-762,4.6,-42.3,69.2
1.152,-762,4.61,-42.3,69.3
1.154,-762,4.62,-42.3,69.4
1.156,-762,4.62,-42.3,69.5
1.158,-762,4.63,-42.3,69.7
1.16,-762,4.64,-42.3,69.8
1.162,-762,4.65,-42.3,69.9
1.164,-760,4.66,-42.2,70
1.166,-760,4.66,-42.2,70.2
1.168,-762,4.67,-42.3,70.3
1.17,-762,4.68,-42.3,70.4
1.173,-760,4.69,-42.2,70.5
1.174,-760,4.7,-42.2,70.7
1.177,-760,4.71,-42.2,70.8
1.179,-760,4.72,-42.2,70.9
1.181,-760,4.72,-42.2,71
1.183,-760,4.73,-42.2,71.2
1.185,-760,4.74,-42.2,71.3
1.187,-760,4.75,-42.2,71.4
1.189,-760,4.76,-42.2,71.5
1.191,-760,4.76,-42.2,71.7
1.193,-760,4.77,-42.2,71.8
1.195,-760,4.78,-42.2,71.9
1.198,-760,4.79,-42.2,72
1.199,-758,4.8,-42.1,72.2
1.202,-758,4.81,-42.1,72.3
1.204,-758,4.82,-42.1,72.4
1.206,-760,4.82,-42.2,72.5
1.208,-760,4.83,-42.2,72.7
1.21,-758,4.84,-42.1,72.8
1.212,-758,4.85,-42.1,72.9
1.214,-758,4.86,-42.1,73
1.216,-758,4.86,-42.1,73.2
1.218,-758,4.87,-42.1,73.3
1.22,-758,4.88,-42.1,73.4
1.223,-758,4.89,-42.1,73.5
1.225,-758,4.9,-42.1,73.7
1.226,-758,4.9,-42.1,73.8
1.229,-758,4.92,-42.1,73.9
1.231,-758,4.92,-42.1,74
1.233,-758,4.93,-42.1,74.2
1.235,-758,4.94,-42.1,74.3
1.237,-758,4.95,-42.1,74.4
1.239,-758,4.96,-42.1,74.5
1.241,-758,4.96,-42.1,74.7
1.243,-758,4.97,-42.1,74.8
1.245,-758,4.98,-42.1,74.9
1.248,-758,4.99,-42.1,75
1.25,-758,5,-42.1,75.2
1.252,-758,5.01,-42.1,75.3
1.254,-758,5.02,-42.1,75.4
1.256,-757,5.02,-42,75.5
1.258,-757,5.03,-42,75.7
1.26,-758,5.04,-42.1,75.8
1.262,-757,5.05,-42,75.9
1.264,-758,5.06,-42.1,76
1.266,-757,5.06,-42,76.2
1.268,-757,5.07,-42,76.3
1.27,-757,5.08,-42,76.4
1.273,-757,5.09,-42,76.5
1.275,-757,5.1,-42,76.7
1.277,-757,5.11,-42,76.8
1.279,-757,5.12,-42,76.9
1.281,-757,5.12,-42,77
1.283,-757,5.13,-42,77.2
1.285,-757,5.14,-42,77.3
1.287,-757,5.15,-42,77.4
1.289,-757,5.16,-42,77.5
1.291,-757,5.16,-42,77.7
1.293,-757,5.17,-42,77.8
1.295,-757,5.18,-42,77.9
1.297,-757,5.19,-42,78
1.3,-757,5.2,-42,78.2
1.302,-757,5.21,-42,78.3
1.304,-757,5.22,-42,78.4
1.306,-757,5.22,-42,78.5
1.308,-757,5.23,-42,78.7
1.31,-757,5.24,-42,78.8
1.312,-757,5.25,-42,78.9
1.314,-757,5.26,-42,79
1.316,-757,5.26,-42,79.2
1.318,-757,5.27,-42,79.3
1.32,-757,5.28,-42,79.4
1.322,-757,5.29,-42,79.5
1.325,-757,5.3,-42,79.7
1.327,-757,5.31,-42,79.8
1.329,-757,5.32,-42,79.9
1.331,-757,5.32,-42,80
1.333,-757,5.33,-42,80.2
1.335,-757,5.34,-42,80.3
1.337,-757,5.35,-42,80.4
1.339,-757,5.36,-42,80.5
1.341,-757,5.36,-42,80.7
1.343,-757,5.37,-42,80.8
1.345,-757,5.38,-42,80.9
1.347,-757,5.39,-42,81
1.35,-757,5.4,-42,81.2
1.352,-757,5.41,-42,81.3
1.354,-757,5.42,-42,81.4
1.356,-757,5.42,-42,81.5
1.358,-757,5.43,-42,81.7
1.36,-757,5.44,-42,81.8
1.362,-757,5.45,-42,81.9
1.364,-757,5.46,-42,82
1.366,-757,5.46,-42,82.2
1.368,-757,5.47,-42,82.3
1.371,-757,5.48,-42,82.4
1.372,-757,5.49,-42,82.5
1.375,-757,5.5,-42,82.7
1.377,-757,5.51,-42,82.8
1.379,-757,5.52,-42,82.9
1.381,-757,5.52,-42,83
1.383,-757,5.53,-42,83.2
1.385,-757,5.54,-42,83.3
1.387,-757,5.55,-42,83.4
1.389,-757,5.56,-42,83.5
1.391,-757,5.56,-42,83.7
1.393,-757,5.57,-42,83.8
1.395,-755,5.58,-41.9,83.9
1.397,-757,5.59,-42,84
1.399,-757,5.6,-42,84.2
1.402,-757,5.61,-42,84.3
1.404,-757,5.62,-42,84.4
1.406,-757,5.62,-42,84.5
1.408,-757,5.63,-42,84.7
1.41,-757,5.64,-42,84.8
1.412,-757,5.65,-42,84.9
1.414,-757,5.66,-42,85
1.416,-757,5.66,-42,85.2
1.418,-757,5.67,-42,85.3
1.42,-757,5.68,-42,85.4
1.422,-757,5.69,-42,85.5
1.424,-757,5.7,-42,85.7
1.427,-757,5.71,-42,85.8
1.429,-757,5.72,-42,85.9
1.431,-757,5.72,-42,86
1.433,-757,5.73,-42,86.2
1.435,-757,5.74,-42,86.3
1.437,-757,5.75,-42,86.4
1.439,-757,5.76,-42,86.5
1.441,-757,5.76,-42,86.7
1.443,-757,5.77,-42,86.8
1.445,-757,5.78,-42,86.9
1.448,-757,5.79,-42,87
1.449,-757,5.8,-42,87.2
1.452,-757,5.81,-42,87.3
1.454,-757,5.82,-42,87.4
1.456,-755,5.82,-41.9,87.5
1.458,-755,5.83,-41.9,87.7
1.46,-757,5.84,-42,87.8
1.462,-757,5.85,-42,87.9
1.464,-757,5.86,-42,88
1.466,-757,5.86,-42,88.2
1.468,-755,5.87,-41.9,88.3
1.47,-757,5.88,-42,88.4
1.473,-757,5.89,-42,88.5
1.474,-757,5.9,-42,88.7
1.477,-755,5.91,-41.9,88.8
1.479,-757,5.92,-42,88.9
1.481,-755,5.92,-41.9,89
1.483,-755,5.93,-41.9,89.2
1.485,-755,5.94,-41.9,89.3
1.487,-755,5.95,-41.9,89.4
1.489,-755,5.96,-41.9,89.5
1.491,-757,5.96,-42,89.7
1.493,-755,5.97,-41.9,89.8
1.495,-755,5.98,-41.9,89.9
1.498,-757,5.99,-42,90
1.5,-757,6,-42,90.2
1.502,-757,6.01,-42,90.3
1.504,-755,6.02,-41.9,90.4
1.506,-755,6.02,-41.9,90.5
1.508,-755,6.03,-41.9,90.7
1.51,-755,6.04,-41.9,90.8
1.512,-757,6.05,-42,90.9
1.514,-757,6.06,-42,91
1.516,-755,6.06,-41.9,91.2
1.518,-755,6.07,-41.9,91.3
1.52,-755,6.08,-41.9,91.4
1.523,-755,6.09,-41.9,91.5
1.525,-755,6.1,-41.9,91.7
1.526,-755,6.1,-41.9,91.8
1.529,-755,6.12,-41.9,91.9
1.531,-755,6.12,-41.9,92
1.533,-755,6.13,-41.9,92.2
1.535,-755,6.14,-41.9,92.3
1.537,-757,6.15,-42,92.4
1.539,-757,6.16,-42,92.5
1.541,-757,6.16,-42,92.7
1.543,-757,6.17,-42,92.8
1.545,-757,6.18,-42,92.9
1.548,-757,6.19,-42,93
1.55,-757,6.2,-42,93.2
1.551,-757,6.2,-42,93.3
1.554,-757,6.22,-42,93.4
1.556,-757,6.22,-42,93.5
1.558,-757,6.23,-42,93.7
1.56,-757,6.24,-42,93.8
1.562,-757,6.25,-42,93.9
1.564,-757,6.26,-42,94
1.566,-757,6.26,-42,94.2
1.568,-757,6.27,-42,94.3
1.57,-757,6.28,-42,94.4
1.573,-757,6.29,-42,94.5
1.575,-757,6.3,-42,94.7
1.577,-757,6.31,-42,94.8
1.579,-757,6.32,-42,94.9
1.581,-757,6.32,-42,95
1.583,-757,6.33,-42,95.2
1.585,-755,6.34,-41.9,95.3
1.587,-757,6.35,-42,95.4
1.589,-757,6.36,-42,95.5
1.591,-755,6.36,-41.9,95.7
1.593,-755,6.37,-41.9,95.8
1.595,-755,6.38,-41.9,95.9
1.597,-757,6.39,-42,96
1.6,-755,6.4,-41.9,96.2
1.602,-757,6.41,-42,96.3
1.604,-757,6.42,-42,96.4
1.606,-757,6.42,-42,96.5
1.608,-757,6.43,-42,96.7
1.61,-757,6.44,-42,96.8
1.612,-757,6.45,-42,96.9
1.614,-757,6.46,-42,97
1.616,-755,6.46,-41.9,97.2
1.618,-757,6.47,-42,97.3
1.62,-757,6.48,-42,97.4
1.622,-757,6.49,-42,97.5
1.625,-757,6.5,-42,97.7
1.627,-757,6.51,-42,97.8
1.629,-757,6.52,-42,97.9
1.631,-755,6.52,-41.9,98
1.633,-757,6.53,-42,98.2
1.635,-757,6.54,-42,98.3
1.637,-757,6.55,-42,98.4
1.639,-755,6.56,-41.9,98.5
1.641,-755,6.56,-41.9,98.7
1.643,-755,6.57,-41.9,98.8
1.645,-755,6.58,-41.9,98.9
*****************************End of Data*****************************