File: MS-1.csv
Position (mm),Force (N),Strain (%),Stress (N/mmï¿½),Time (sec)
0.0,-1.667,0.0,-0.0849,0.0
0.004,53.3,0.016,2.72,0.484
0.012,173.3,0.048,8.83,0.922
0.019,265,0.076,13.5,1.359
0.027,320,0.108,16.3,1.797
0.034,360,0.136,18.33,2.23
0.041,400,0.164,20.4,2.67
0.049,435,0.196,22.2,3.11
0.056,470,0.224,23.9,3.55
0.063,507,0.252,25.8,3.98
0.071,538,0.284,27.4,4.42
0.078,572,0.312,29.1,4.86
0.085,603,0.34,30.7,5.3
0.092,633,0.368,32.3,5.73
0.1,667,0.4,34,6.17
0.107,700,0.428,35.7,6.61
0.114,733,0.456,37.3,7.05
0.122,767,0.488,39,7.48
0.129,798,0.516,40.7,7.92
0.136,832,0.544,42.4,8.36
0.143,863,0.572,44,8.8
0.151,895,0.604,45.6,9.23
0.158,930,0.632,47.4,9.67
0.165,963,0.66,49.1,10.11
0.172,998,0.688,50.8,10.55
0.18,1032,0.72,52.5,10.98
0.187,1063,0.748,54.2,11.42
0.194,1097,0.776,55.9,11.86
0.202,1132,0.808,57.6,12.3
0.209,1165,0.836,59.3,12.73
0.216,1200,0.864,61.1,13.17
0.224,1233,0.896,62.8,13.61
0.231,1265,0.924,64.4,14.05
0.238,1297,0.952,66,14.48
0.245,1330,0.98,67.7,14.92
0.253,1363,1.012,69.4,15.36
0.26,1397,1.04,71.1,15.8
0.267,1432,1.068,72.9,16.23
0.275,1465,1.1,74.6,16.67
0.282,1497,1.128,76.2,17.11
0.289,1528,1.156,77.8,17.55
0.296,1562,1.184,79.5,17.98
0.304,1595,1.216,81.2,18.42
0.311,1628,1.244,82.9,18.86
0.318,1662,1.272,84.6,19.3
0.326,1695,1.304,86.3,19.73
0.333,1727,1.332,87.9,20.2
0.34,1760,1.36,89.6,20.6
0.347,1792,1.388,91.2,21
0.355,1827,1.42,93,21.5
0.362,1862,1.448,94.8,21.9
0.369,1897,1.476,96.6,22.4
0.377,1930,1.508,98.3,22.8
0.384,1962,1.536,99.9,23.2
0.391,1995,1.564,101.6,23.7
0.399,2030,1.596,103.3,24.1
0.406,2060,1.624,105.1,24.5
0.413,2100,1.652,106.9,25
0.42,2130,1.68,108.6,25.4
0.428,2160,1.712,110.3,25.9
0.435,2200,1.74,112.1,26.3
0.442,2230,1.768,113.7,26.7
0.45,2270,1.8,115.6,27.2
0.457,2300,1.828,117.3,27.6
0.464,2340,1.856,119.1,28
0.472,2380,1.888,121,28.5
0.479,2410,1.916,122.7,28.9
0.486,2440,1.944,124.4,29.4
0.493,2480,1.972,126.1,29.8
0.501,2510,2,127.9,30.2
0.508,2550,2.03,129.7,30.7
0.515,2580,2.06,131.6,31.1
0.523,2620,2.09,133.4,31.5
0.53,2660,2.12,135.2,32
0.537,2690,2.15,136.9,32.4
0.544,2720,2.18,138.8,32.9
0.552,2760,2.21,140.5,33.3
0.559,2800,2.24,142.3,33.7
0.566,2830,2.26,144.2,34.2
0.574,2870,2.3,146.1,34.6
0.581,2900,2.32,148,35
0.588,2940,2.35,149.6,35.5
0.595,2970,2.38,151.4,35.9
0.603,3010,2.41,153.2,36.4
0.61,3050,2.44,155.2,36.8
0.617,3080,2.47,157.1,37.2
0.625,3120,2.5,159,37.7
0.632,3160,2.53,160.8,38.1
0.639,3190,2.56,162.6,38.5
0.646,3230,2.58,164.4,39
0.654,3260,2.62,166.3,39.4
0.661,3300,2.64,168.1,39.9
0.668,3340,2.67,170,40.3
0.676,3380,2.7,171.9,40.7
0.683,3410,2.73,173.7,41.2
0.69,3440,2.76,175.5,41.6
0.697,3480,2.79,177.4,42
0.705,3520,2.82,179.4,42.5
0.712,3560,2.85,181.3,42.9
0.719,3600,2.88,183.2,43.4
0.727,3630,2.91,185,43.8
0.734,3670,2.94,186.9,44.2
0.741,3710,2.96,188.8,44.7
0.749,3740,3,190.6,45.1
0.756,3780,3.02,192.6,45.5
0.763,3820,3.05,194.6,46
0.77,3860,3.08,196.5,46.4
0.778,3900,3.11,198.5,46.9
0.785,3930,3.14,200,47.3
0.792,3970,3.17,202,47.7
0.8,4010,3.2,204,48.2
0.807,4050,3.23,206,48.6
0.814,4090,3.26,208,49
0.821,4120,3.28,210,49.5
0.829,4160,3.32,212,49.9
0.836,4200,3.34,214,50.4
0.843,4240,3.37,216,50.8
0.851,4280,3.4,218,51.2
0.858,4320,3.43,220,51.7
0.865,4360,3.46,222,52.1
0.873,4390,3.49,224,52.5
0.88,4430,3.52,226,53
0.887,4470,3.55,228,53.4
0.894,4510,3.58,230,53.9
0.902,4550,3.61,232,54.3
0.909,4590,3.64,234,54.7
0.916,4630,3.66,236,55.2
0.923,4660,3.69,238,55.6
0.931,4700,3.72,239,56
0.938,4740,3.75,241,56.5
0.946,4780,3.78,243,56.9
0.953,4820,3.81,246,57.4
0.96,4860,3.84,248,57.8
0.967,4900,3.87,250,58.2
0.975,4940,3.9,252,58.7
0.982,4980,3.93,253,59.1
0.989,5020,3.96,255,59.5
0.997,5060,3.99,258,60
1.004,5100,4.02,260,60.4
1.011,5140,4.04,262,60.9
1.018,5180,4.07,264,61.3
1.026,5220,4.1,266,61.7
1.033,5260,4.13,268,62.2
1.04,5300,4.16,270,62.6
1.048,5340,4.19,272,63
1.055,5380,4.22,274,63.5
1.062,5420,4.25,276,63.9
1.069,5460,4.28,278,64.4
1.077,5500,4.31,280,64.8
1.084,5530,4.34,282,65.2
1.091,5570,4.36,284,65.7
1.099,5620,4.4,286,66.1
1.106,5660,4.42,288,66.5
1.113,5700,4.45,290,67
1.12,5740,4.48,292,67.4
1.128,5780,4.51,294,67.9
1.135,5820,4.54,296,68.3
1.142,5860,4.57,298,68.7
1.15,5900,4.6,300,69.2
1.157,5940,4.63,302,69.6
1.164,5980,4.66,304,70
1.171,6020,4.68,306,70.5
1.179,6060,4.72,309,70.9
1.186,6100,4.74,311,71.4
1.193,6140,4.77,313,71.8
1.201,6180,4.8,315,72.2
1.208,6220,4.83,317,72.7
1.215,6260,4.86,319,73.1
1.222,6300,4.89,321,73.5
1.23,6340,4.92,323,74
1.237,6380,4.95,325,74.4
1.245,6430,4.98,327,74.9
1.252,6470,5.01,330,75.3
1.259,6510,5.04,331,75.7
1.266,6550,5.06,334,76.2
1.274,6590,5.1,336,76.6
1.281,6630,5.12,338,77
1.288,6670,5.15,340,77.5
1.296,6720,5.18,342,77.9
1.303,6760,5.21,344,78.4
1.31,6800,5.24,346,78.8
1.317,6840,5.27,348,79.2
1.325,6880,5.3,350,79.7
1.332,6920,5.33,353,80.1
1.339,6960,5.36,355,80.5
1.347,7010,5.39,357,81
1.354,7050,5.42,359,81.4
1.361,7090,5.44,361,81.9
1.368,7130,5.47,363,82.3
1.376,7170,5.5,365,82.7
1.383,7210,5.53,367,83.2
1.39,7260,5.56,370,83.6
1.398,7300,5.59,372,84
1.405,6920,5.62,352,84.5
1.412,6340,5.65,323,84.9
1.419,6290,5.68,320,85.4
1.427,6280,5.71,320,85.8
1.434,6280,5.74,320,86.2
1.441,6280,5.76,320,86.7
1.449,6290,5.8,320,87.1
1.456,6290,5.82,320,87.5
1.463,6290,5.85,320,88
1.47,6290,5.88,320,88.4
1.478,6290,5.91,321,88.9
1.485,6300,5.94,321,89.3
1.492,6300,5.97,321,89.7
1.5,6300,6,321,90.2
1.507,6300,6.03,321,90.6
1.514,6300,6.06,321,91
1.521,6290,6.08,320,91.5
1.529,6280,6.12,320,91.9
1.536,6280,6.14,320,92.4
1.543,6270,6.17,319,92.8
1.551,6280,6.2,320,93.2
1.558,6280,6.23,320,93.7
1.565,6270,6.26,319,94.1
1.572,6230,6.29,317,94.5
1.58,6220,6.32,317,95
1.587,6190,6.35,315,95.4
1.594,6180,6.38,315,95.9
1.602,6180,6.41,315,96.3
1.609,6190,6.44,315,96.7
1.616,6220,6.46,317,97.2
1.623,6250,6.49,318,97.6
1.631,6280,6.52,320,98
1.638,6300,6.55,321,98.5
1.645,6330,6.58,323,98.9
1.653,6360,6.61,324,99.4
1.66,6380,6.64,325,99.8
1.667,6400,6.67,326,100.2
1.675,6420,6.7,327,100.7
1.682,6440,6.73,328,101.1
1.689,6460,6.76,329,101.5
1.696,6460,6.78,329,102
1.704,6440,6.82,328,102.4
1.711,6440,6.84,328,102.9
1.718,6450,6.87,328,103.3
1.726,6450,6.9,328,103.7
1.733,6420,6.93,327,104.2
1.74,6410,6.96,326,104.6
1.748,6400,6.99,326,105
1.755,6380,7.02,325,105.5
1.762,6370,7.05,324,105.9
1.769,6380,7.08,325,106.4
1.777,6390,7.11,325,106.8
1.784,6400,7.14,326,107.2
1.791,6400,7.16,326,107.7
1.799,6410,7.2,326,108.1
1.806,6420,7.22,327,108.5
1.813,6440,7.25,328,109
1.82,6440,7.28,328,109.4
1.828,6450,7.31,328,109.9
1.835,6440,7.34,328,110.3
1.843,6420,7.37,327,110.7
1.85,6380,7.4,325,111.2
1.857,6340,7.43,323,111.6
1.864,6340,7.46,323,112
1.871,6340,7.48,323,112.5
1.879,6350,7.52,323,112.9
1.886,6360,7.54,324,113.4
1.893,6360,7.57,324,113.8
1.901,6370,7.6,325,114.2
1.908,6380,7.63,325,114.7
1.915,6400,7.66,326,115.1
1.922,6400,7.69,326,115.5
1.93,6410,7.72,326,116
1.937,6410,7.75,327,116.4
1.945,6390,7.78,325,116.9
1.952,6360,7.81,324,117.3
1.959,6350,7.84,324,117.7
1.966,6360,7.86,324,118.2
1.974,6360,7.9,324,118.6
1.981,6370,7.92,325,119
1.988,6360,7.95,324,119.5
1.995,6360,7.98,324,119.9
2,6370,8.01,324,120.4
2.01,6380,8.04,325,120.8
2.02,6390,8.07,326,121.2
2.02,6410,8.1,326,121.7
2.03,6420,8.13,327,122.1
2.04,6420,8.16,327,122.5
2.05,6440,8.19,328,123
2.05,6460,8.22,329,123.4
2.06,6480,8.24,330,123.9
2.07,6500,8.27,331,124.3
2.08,6510,8.3,332,124.7
2.08,6510,8.33,332,125.2
2.09,6520,8.36,332,125.6
2.1,6500,8.39,331,126
2.1,6480,8.42,330,126.5
2.11,6480,8.45,330,126.9
2.12,6500,8.48,331,127.4
2.13,6520,8.51,332,127.8
2.13,6530,8.54,333,128.2
2.14,6510,8.56,332,128.7
2.15,6500,8.6,331,129.1
2.16,6500,8.62,331,129.5
2.16,6510,8.65,332,130
2.17,6520,8.68,332,130.4
2.18,6510,8.71,332,130.9
2.18,6530,8.74,332,131.3
2.19,6540,8.77,333,131.7
2.2,6540,8.8,333,132.2
2.21,6540,8.83,333,132.6
2.21,6570,8.86,335,133
2.22,6600,8.89,336,133.5
2.23,6620,8.92,337,133.9
2.24,6660,8.94,339,134.4
2.24,6680,8.97,340,134.8
2.25,6700,9,341,135.2
2.26,6720,9.03,343,135.7
2.26,6740,9.06,343,136.1
2.27,6760,9.09,344,136.5
2.28,6780,9.12,345,137
2.29,6800,9.15,346,137.4
2.29,6820,9.18,347,137.9
2.3,6840,9.21,348,138.3
2.31,6850,9.24,349,138.7
2.32,6860,9.26,350,139.2
2.32,6880,9.3,351,139.6
2.33,6900,9.32,351,140
2.34,6920,9.35,352,140.5
2.35,6930,9.38,353,140.9
2.35,6940,9.41,354,141.4
2.36,6960,9.44,354,141.8
2.37,6970,9.47,355,142.2
2.38,6970,9.5,355,142.7
2.38,6990,9.53,356,143.1
2.39,7000,9.56,357,143.5
2.4,7020,9.58,357,144
2.4,7030,9.62,358,144.4
2.41,7040,9.64,359,144.9
2.42,7060,9.67,359,145.3
2.43,7070,9.7,360,145.7
2.43,7090,9.73,361,146.2
2.44,7100,9.76,362,146.6
2.45,7110,9.79,362,147
2.46,7120,9.82,363,147.5
2.46,7130,9.85,363,147.9
2.47,7150,9.88,364,148.4
2.48,7160,9.91,365,148.8
2.48,7170,9.94,365,149.2
2.49,7180,9.96,366,149.7
2.5,7190,9.99,366,150.1
2.51,7200,10.02,367,150.5
2.51,7220,10.05,367,151
2.52,7230,10.08,368,151.4
2.53,7240,10.11,369,151.9
2.54,7250,10.14,369,152.3
2.54,7260,10.17,370,152.7
2.55,7270,10.2,370,153.2
2.56,7280,10.23,371,153.6
2.56,7290,10.26,371,154
2.57,7310,10.29,372,154.5
2.58,7320,10.32,373,154.9
2.59,7330,10.34,373,155.4
2.59,7340,10.37,374,155.8
2.6,7350,10.4,374,156.2
2.61,7360,10.43,375,156.7
2.62,7370,10.46,375,157.1
2.62,7380,10.49,376,157.5
2.63,7390,10.52,376,158
2.64,7400,10.55,377,158.4
2.64,7410,10.58,377,158.9
2.65,7420,10.61,378,159.3
2.66,7430,10.64,378,159.7
2.67,7440,10.66,379,160.2
2.67,7450,10.7,379,160.6
2.68,7460,10.72,380,161
2.69,7470,10.75,380,161.5
2.7,7480,10.78,381,161.9
2.7,7490,10.81,381,162.4
2.71,7500,10.84,382,162.8
2.72,7510,10.87,382,163.2
2.72,7520,10.9,383,163.7
2.73,7530,10.93,383,164.1
2.74,7540,10.96,384,164.5
2.75,7540,10.98,384,165
2.75,7550,11.02,385,165.4
2.76,7560,11.04,385,165.9
2.77,7570,11.07,386,166.3
2.78,7580,11.1,386,166.7
2.78,7590,11.13,387,167.2
2.79,7600,11.16,387,167.6
2.8,7610,11.19,387,168
2.8,7620,11.22,388,168.5
2.81,7630,11.25,389,168.9
2.82,7640,11.28,389,169.4
2.83,7650,11.31,389,169.8
2.83,7660,11.34,390,170.2
2.84,7660,11.36,390,170.7
2.85,7670,11.4,391,171.1
2.86,7680,11.42,391,171.5
2.86,7690,11.45,392,172
2.87,7700,11.48,392,172.4
2.88,7710,11.51,393,172.9
2.88,7720,11.54,393,173.3
2.89,7720,11.57,393,173.7
2.9,7730,11.6,394,174.2
2.91,7740,11.63,394,174.6
2.91,7750,11.66,395,175
2.92,7760,11.69,395,175.5
2.93,7770,11.72,396,175.9
2.94,7780,11.74,396,176.4
2.94,7790,11.77,397,176.8
2.95,7790,11.8,397,177.2
2.96,7800,11.83,397,177.7
2.96,7810,11.86,398,178.1
2.97,7820,11.89,398,178.5
2.98,7830,11.92,399,179
2.99,7840,11.95,399,179.4
2.99,7840,11.98,400,179.9
3,7860,12.01,400,180.3
3.01,7860,12.04,401,180.7
3.02,7870,12.06,401,181.2
3.02,7880,12.1,401,181.6
3.03,7890,12.12,402,182
3.04,7900,12.15,402,182.5
3.04,7900,12.18,403,182.9
3.05,7910,12.21,403,183.4
3.06,7920,12.24,403,183.8
3.07,7930,12.27,404,184.2
3.08,7940,12.3,404,184.7
3.08,7950,12.33,405,185.1
3.09,7960,12.36,405,185.5
3.1,7960,12.38,405,186
3.1,7970,12.42,406,186.4
3.11,7980,12.44,406,186.9
3.12,7990,12.47,407,187.3
3.13,8000,12.5,407,187.7
3.13,8000,12.53,408,188.2
3.14,8010,12.56,408,188.6
3.15,8020,12.59,408,189
3.16,8030,12.62,409,189.5
3.16,8040,12.65,409,189.9
3.17,8040,12.68,410,190.4
3.18,8050,12.71,410,190.8
3.18,8060,12.74,410,191.2
3.19,8060,12.76,411,191.7
3.2,8070,12.8,411,192.1
3.21,8080,12.82,412,192.5
3.21,8090,12.85,412,193
3.22,8100,12.88,412,193.4
3.23,8100,12.91,413,193.9
3.24,8110,12.94,413,194.3
3.24,8120,12.97,414,194.7
3.25,8130,13,414,195.2
3.26,8140,13.03,414,195.6
3.26,8140,13.06,415,196
3.27,8150,13.08,415,196.5
3.28,8160,13.12,416,196.9
3.29,8170,13.14,416,197.4
3.29,8170,13.17,416,197.8
3.3,8180,13.2,417,198.2
3.31,8190,13.23,417,198.7
3.32,8200,13.26,418,199.1
3.32,8200,13.29,418,199.5
3.33,8210,13.32,418,200
3.34,8220,13.35,418,200
3.34,8220,13.38,419,201
3.35,8230,13.41,419,201
3.36,8240,13.44,420,202
3.37,8250,13.46,420,202
3.37,8260,13.49,420,203
3.38,8260,13.52,421,203
3.39,8270,13.55,421,203
3.4,8280,13.58,422,204
3.4,8290,13.61,422,204
3.41,8290,13.64,422,205
3.42,8300,13.67,423,205
3.42,8300,13.7,423,206
3.43,8310,13.73,423,206
3.44,8320,13.76,424,207
3.45,8330,13.79,424,207
3.45,8340,13.82,424,207
3.46,8340,13.84,425,208
3.47,8350,13.87,425,208
3.48,8360,13.9,426,209
3.48,8360,13.93,426,209
3.49,8370,13.96,426,210
3.5,8380,13.99,427,210
3.5,8380,14.02,427,210
3.51,8390,14.05,427,211
3.52,8400,14.08,428,211
3.53,8400,14.11,428,212
3.53,8410,14.14,428,212
3.54,8420,14.16,429,213
3.55,8420,14.2,429,213
3.56,8430,14.22,429,214
3.56,8440,14.25,430,214
3.57,8440,14.28,430,214
3.58,8450,14.31,430,215
3.58,8460,14.34,431,215
3.59,8460,14.37,431,216
3.6,8470,14.4,431,216
3.61,8480,14.43,432,217
3.61,8480,14.46,432,217
3.62,8490,14.48,432,217
3.63,8490,14.52,433,218
3.64,8500,14.54,433,218
3.64,8510,14.57,433,219
3.65,8510,14.6,434,219
3.66,8520,14.63,434,220
3.66,8520,14.66,434,220
3.67,8530,14.69,435,221
3.68,8540,14.72,435,221
3.69,8540,14.75,435,221
3.69,8550,14.78,436,222
3.7,8560,14.81,436,222
3.71,8560,14.84,436,223
3.72,8570,14.86,436,223
3.72,8580,14.9,437,224
3.73,8580,14.92,437,224
3.74,8590,14.95,438,224
3.74,8600,14.98,438,225
3.75,8600,15.01,438,225
3.76,8610,15.04,438,226
3.77,8610,15.07,439,226
3.78,8620,15.1,439,227
3.78,8630,15.13,439,227
3.79,8630,15.16,440,228
3.8,8640,15.18,440,228
3.8,8640,15.22,440,228
3.81,8650,15.24,440,229
3.82,8660,15.27,441,229
3.83,8660,15.3,441,230
3.83,8670,15.33,441,230
3.84,8680,15.36,442,231
3.85,8680,15.39,442,231
3.86,8680,15.42,442,231
3.86,8690,15.45,443,232
3.87,8700,15.48,443,232
3.88,8700,15.51,443,233
3.88,8710,15.54,444,233
3.89,8710,15.56,444,234
3.9,8720,15.59,444,234
3.91,8720,15.62,444,235
3.91,8730,15.65,445,235
3.92,8740,15.68,445,235
3.93,8740,15.71,445,236
3.94,8750,15.74,446,236
3.94,8750,15.77,446,237
3.95,8760,15.8,446,237
3.96,8760,15.83,446,238
3.96,8770,15.86,447,238
3.97,8780,15.89,447,238
3.98,8780,15.92,447,239
3.99,8790,15.94,448,239
3.99,8790,15.97,448,240
4,8800,16,448,240
4.01,8800,16.03,448,241
4.02,8810,16.06,449,241
4.02,8820,16.09,449,242
4.03,8820,16.12,449,242
4.04,8830,16.15,450,242
4.04,8830,16.18,450,243
4.05,8830,16.21,450,243
4.06,8840,16.24,450,244
4.07,8850,16.26,451,244
4.07,8850,16.3,451,245
4.08,8860,16.32,451,245
4.09,8860,16.35,451,245
4.1,8870,16.38,452,246
4.1,8870,16.41,452,246
4.11,8880,16.44,452,247
4.12,8880,16.47,452,247
4.12,8890,16.5,453,248
4.13,8900,16.53,453,248
4.14,8900,16.56,453,249
4.15,8900,16.58,453,249
4.15,8910,16.62,454,249
4.16,8910,16.64,454,250
4.17,8920,16.67,454,250
4.18,8920,16.7,455,251
4.18,8930,16.73,455,251
4.19,8930,16.76,455,252
4.2,8940,16.79,455,252
4.2,8940,16.82,455,252
4.21,8950,16.85,456,253
4.22,8950,16.88,456,253
4.23,8960,16.91,456,254
4.23,8960,16.94,456,254
4.24,8960,16.96,457,255
4.25,8970,17,457,255
4.26,8980,17.02,457,256
4.26,8980,17.05,457,256
4.27,8990,17.08,458,256
4.28,8990,17.11,458,257
4.28,9000,17.14,458,257
4.29,9000,17.17,458,258
4.3,9000,17.2,459,258
4.31,9010,17.23,459,259
4.31,9020,17.26,459,259
4.32,9020,17.28,459,259
4.33,9030,17.32,460,260
4.34,9030,17.34,460,260
4.34,9030,17.37,460,261
4.35,9040,17.4,460,261
4.36,9040,17.43,461,262
4.36,9050,17.46,461,262
4.37,9060,17.49,461,263
4.38,9060,17.52,461,263
4.39,9060,17.55,462,263
4.39,9070,17.58,462,264
4.4,9070,17.61,462,264
4.41,9080,17.64,462,265
4.42,9080,17.66,463,265
4.42,9080,17.7,463,266
4.43,9090,17.72,463,266
4.44,9100,17.75,463,266
4.45,9100,17.78,463,267
4.45,9100,17.81,464,267
4.46,9110,17.84,464,268
4.47,9110,17.87,464,268
4.48,9120,17.9,464,269
4.48,9120,17.93,464,269
4.49,9120,17.96,465,270
4.5,9130,17.99,465,270
4.5,9140,18.02,465,270
4.51,9140,18.04,465,271
4.52,9140,18.07,466,271
4.52,9140,18.1,466,272
4.53,9150,18.13,466,272
4.54,9150,18.16,466,273
4.55,9160,18.19,466,273
4.56,9160,18.22,467,273
4.56,9170,18.25,467,274
4.57,9170,18.28,467,274
4.58,9180,18.31,467,275
4.58,9180,18.34,467,275
4.59,9180,18.36,468,276
4.6,9190,18.4,468,276
4.61,9190,18.42,468,277
4.61,9200,18.45,468,277
4.62,9200,18.48,469,277
4.63,9200,18.51,469,278
4.64,9210,18.54,469,278
4.64,9210,18.57,469,279
4.65,9220,18.6,469,279
4.66,9220,18.63,470,280
4.66,9220,18.66,470,280
4.67,9230,18.68,470,280
4.68,9230,18.72,470,281
4.69,9240,18.74,470,281
4.69,9240,18.77,471,282
4.7,9240,18.8,471,282
4.71,9250,18.83,471,283
4.72,9260,18.86,471,283
4.72,9260,18.89,471,284
4.73,9260,18.92,472,284
4.74,9260,18.95,472,284
4.74,9270,18.98,472,285
4.75,9270,19.01,472,285
4.76,9280,19.04,472,286
4.77,9280,19.06,473,286
4.77,9280,19.09,473,287
4.78,9280,19.12,473,287
4.79,9290,19.15,473,287
4.8,9290,19.18,473,288
4.8,9300,19.21,474,288
4.81,9300,19.24,474,289
4.82,9310,19.27,474,289
4.82,9310,19.3,474,290
4.83,9310,19.33,474,290
4.84,9320,19.36,474,291
4.85,9320,19.39,475,291
4.85,9320,19.42,475,291
4.86,9330,19.44,475,292
4.87,9330,19.47,475,292
4.88,9340,19.5,475,293
4.88,9340,19.53,476,293
4.89,9340,19.56,476,294
4.9,9340,19.59,476,294
4.9,9350,19.62,476,294
4.91,9350,19.65,476,295
4.92,9360,19.68,477,295
4.93,9360,19.71,477,296
4.93,9360,19.74,477,296
4.94,9370,19.76,477,297
4.95,9370,19.8,477,297
4.96,9380,19.82,477,298
4.96,9380,19.85,478,298
4.97,9380,19.88,478,298
4.98,9380,19.91,478,299
4.98,9380,19.94,478,299
4.99,9390,19.97,478,300
5,9400,20,478,300
5.01,9400,20,479,301
5.01,9400,20.1,479,301
5.02,9400,20.1,479,301
5.03,9400,20.1,479,302
5.04,9410,20.1,479,302
5.04,9410,20.2,479,303
5.05,9420,20.2,480,303
5.06,9420,20.2,480,304
5.06,9420,20.3,480,304
5.07,9430,20.3,480,305
5.08,9430,20.3,480,305
5.09,9430,20.3,480,305
5.1,9440,20.4,481,306
5.1,9440,20.4,481,306
5.11,9440,20.4,481,307
5.12,9450,20.5,481,307
5.12,9450,20.5,481,308
5.13,9450,20.5,481,308
5.14,9460,20.6,482,308
5.15,9460,20.6,482,309
5.15,9460,20.6,482,309
5.16,9470,20.6,482,310
5.17,9470,20.7,482,310
5.18,9470,20.7,482,311
5.18,9470,20.7,482,311
5.19,9480,20.8,483,312
5.2,9480,20.8,483,312
5.2,9480,20.8,483,312
5.21,9490,20.8,483,313
5.22,9490,20.9,483,313
5.23,9490,20.9,483,314
5.23,9500,20.9,484,314
5.24,9500,21,484,315
5.25,9500,21,484,315
5.26,9500,21,484,315
5.26,9510,21,484,316
5.27,9510,21.1,484,316
5.28,9510,21.1,484,317
5.28,9510,21.1,485,317
5.29,9520,21.2,485,318
5.3,9520,21.2,485,318
5.31,9530,21.2,485,319
5.31,9530,21.3,485,319
5.32,9530,21.3,485,319
5.33,9530,21.3,486,320
5.34,9540,21.3,486,320
5.34,9540,21.4,486,321
5.35,9540,21.4,486,321
5.36,9550,21.4,486,322
5.36,9550,21.5,486,322
5.37,9550,21.5,486,322
5.38,9550,21.5,487,323
5.39,9560,21.5,487,323
5.39,9560,21.6,487,324
5.4,9560,21.6,487,324
5.41,9570,21.6,487,325
5.42,9570,21.7,487,325
5.42,9570,21.7,487,326
5.43,9570,21.7,488,326
5.44,9580,21.7,488,326
5.44,9580,21.8,488,327
5.45,9580,21.8,488,327
5.46,9580,21.8,488,328
5.47,9590,21.9,488,328
5.47,9590,21.9,488,329
5.48,9590,21.9,488,329
5.49,9600,22,489,329
5.5,9600,22,489,330
5.5,9600,22,489,330
5.51,9600,22,489,331
5.52,9600,22.1,489,331
5.52,9610,22.1,489,332
5.53,9610,22.1,489,332
5.54,9610,22.2,490,333
5.55,9620,22.2,490,333
5.55,9620,22.2,490,333
5.56,9620,22.2,490,334
5.57,9620,22.3,490,334
5.58,9620,22.3,490,335
5.58,9630,22.3,490,335
5.59,9630,22.4,491,336
5.6,9640,22.4,491,336
5.6,9640,22.4,491,336
5.61,9640,22.4,491,337
5.62,9640,22.5,491,337
5.63,9640,22.5,491,338
5.63,9640,22.5,491,338
5.64,9650,22.6,491,339
5.65,9650,22.6,492,339
5.66,9650,22.6,492,340
5.66,9660,22.7,492,340
5.67,9660,22.7,492,340
5.68,9660,22.7,492,341
5.68,9660,22.7,492,341
5.69,9670,22.8,492,342
5.7,9670,22.8,492,342
5.71,9670,22.8,492,343
5.71,9670,22.9,492,343
5.72,9670,22.9,493,343
5.73,9680,22.9,493,344
5.74,9680,22.9,493,344
5.74,9680,23,493,345
5.75,9680,23,493,345
5.76,9690,23,493,346
5.76,9690,23.1,493,346
5.77,9690,23.1,494,347
5.78,9690,23.1,494,347
5.79,9700,23.1,494,347
5.79,9700,23.2,494,348
5.8,9700,23.2,494,348
5.81,9700,23.2,494,349
5.82,9700,23.3,494,349
5.82,9700,23.3,494,350
5.83,9710,23.3,494,350
5.84,9710,23.4,495,350
5.84,9720,23.4,495,351
5.85,9720,23.4,495,351
5.86,9720,23.4,495,352
5.87,9720,23.5,495,352
5.88,9720,23.5,495,353
5.88,9720,23.5,495,353
5.89,9730,23.6,495,354
5.9,9730,23.6,496,354
5.9,9730,23.6,496,354
5.91,9730,23.6,496,355
5.92,9730,23.7,496,355
5.93,9740,23.7,496,356
5.93,9740,23.7,496,356
5.94,9740,23.8,496,357
5.95,9740,23.8,496,357
5.96,9740,23.8,496,357
5.96,9740,23.8,496,358
5.97,9750,23.9,496,358
5.98,9750,23.9,497,359
5.98,9750,23.9,497,359
5.99,9760,24,497,360
6,9760,24,497,360
6.01,9760,24,497,361
6.01,9760,24.1,497,361
6.02,9760,24.1,497,361
6.03,9760,24.1,497,362
6.04,9770,24.1,497,362
6.04,9770,24.2,498,363
6.05,9770,24.2,498,363
6.06,9770,24.2,498,364
6.06,9770,24.3,498,364
6.07,9780,24.3,498,364
6.08,9780,24.3,498,365
6.09,9780,24.3,498,365
6.09,9780,24.4,498,366
6.1,9780,24.4,498,366
6.11,9780,24.4,498,367
6.12,9790,24.5,498,367
6.12,9790,24.5,499,368
6.13,9790,24.5,499,368
6.14,9800,24.5,499,368
6.14,9800,24.6,499,369
6.15,9800,24.6,499,369
6.16,9800,24.6,499,370
6.17,9800,24.7,499,370
6.17,9800,24.7,499,371
6.18,9800,24.7,499,371
6.19,9810,24.8,499,371
6.2,9810,24.8,499,372
6.2,9810,24.8,500,372
6.21,9810,24.8,500,373
6.22,9810,24.9,500,373
6.22,9820,24.9,500,374
6.23,9820,24.9,500,374
6.24,9820,25,500,375
6.25,9820,25,500,375
6.25,9820,25,500,375
6.26,9820,25,500,376
6.27,9830,25.1,500,376
6.28,9830,25.1,500,377
6.28,9830,25.1,501,377
6.29,9830,25.2,501,378
6.3,9830,25.2,501,378
6.3,9830,25.2,501,378
6.31,9840,25.2,501,379
6.32,9840,25.3,501,379
6.33,9840,25.3,501,380
6.33,9840,25.3,501,380
6.34,9840,25.4,501,381
6.35,9840,25.4,501,381
6.36,9840,25.4,501,382
6.36,9850,25.5,501,382
6.37,9850,25.5,502,382
6.38,9850,25.5,502,383
6.38,9850,25.5,502,383
6.39,9850,25.6,502,384
6.4,9850,25.6,502,384
6.41,9860,25.6,502,385
6.41,9860,25.7,502,385
6.42,9860,25.7,502,385
6.43,9860,25.7,502,386
6.44,9860,25.7,502,386
6.44,9860,25.8,502,387
6.45,9860,25.8,502,387
6.46,9870,25.8,503,388
6.46,9870,25.9,503,388
6.47,9870,25.9,503,389
6.48,9870,25.9,503,389
6.49,9880,25.9,503,389
6.49,9880,26,503,390
6.5,9880,26,503,390
6.51,9880,26,503,391
6.52,9880,26.1,503,391
6.52,9880,26.1,503,392
6.53,9880,26.1,503,392
6.54,9880,26.2,503,392
6.54,9880,26.2,503,393
6.55,9880,26.2,503,393
6.56,9890,26.2,504,394
6.57,9890,26.3,504,394
6.58,9890,26.3,504,395
6.58,9900,26.3,504,395
6.59,9900,26.4,504,396
6.6,9900,26.4,504,396
6.6,9900,26.4,504,396
6.61,9900,26.4,504,397
6.62,9900,26.5,504,397
6.63,9900,26.5,504,398
6.63,9900,26.5,504,398
6.64,9900,26.6,504,399
6.65,9900,26.6,504,399
6.66,9900,26.6,504,399
6.66,9910,26.6,505,400
6.67,9910,26.7,505,400
6.68,9910,26.7,505,401
6.68,9910,26.7,505,401
6.69,9910,26.8,505,402
6.7,9910,26.8,505,402
6.71,9920,26.8,505,403
6.71,9920,26.9,505,403
6.72,9920,26.9,505,403
6.73,9920,26.9,505,404
6.74,9920,26.9,505,404
6.74,9920,27,505,405
6.75,9920,27,505,405
6.76,9920,27,505,406
6.76,9930,27.1,506,406
6.77,9930,27.1,506,406
6.78,9930,27.1,506,407
6.79,9930,27.1,506,407
6.79,9930,27.2,506,408
6.8,9930,27.2,506,408
6.81,9930,27.2,506,409
6.82,9940,27.3,506,409
6.82,9940,27.3,506,410
6.83,9940,27.3,506,410
6.84,9940,27.3,506,410
6.84,9940,27.4,506,411
6.85,9940,27.4,506,411
6.86,9940,27.4,506,412
6.87,9940,27.5,506,412
6.87,9950,27.5,507,413
6.88,9950,27.5,507,413
6.89,9940,27.6,506,413
6.9,9950,27.6,507,414
6.9,9950,27.6,507,414
6.91,9950,27.6,507,415
6.92,9950,27.7,507,415
6.92,9950,27.7,507,416
6.93,9950,27.7,507,416
6.94,9960,27.8,507,417
6.95,9960,27.8,507,417
6.95,9960,27.8,507,417
6.96,9960,27.8,507,418
6.97,9960,27.9,507,418
6.98,9960,27.9,507,419
6.98,9960,27.9,507,419
6.99,9960,28,507,420
7,9960,28,507,420
7,9960,28,508,420
7.01,9970,28,508,421
7.02,9970,28.1,508,421
7.03,9970,28.1,508,422
7.03,9970,28.1,508,422
7.04,9970,28.2,508,423
7.05,9970,28.2,508,423
7.06,9970,28.2,508,424
7.06,9970,28.3,508,424
7.07,9980,28.3,508,424
7.08,9970,28.3,508,425
7.08,9970,28.3,508,425
7.09,9980,28.4,508,426
7.1,9980,28.4,508,426
7.11,9980,28.4,508,427
7.11,9980,28.5,508,427
7.12,9980,28.5,508,427
7.13,9980,28.5,508,428
7.14,9980,28.5,508,428
7.14,9980,28.6,508,429
7.15,9980,28.6,508,429
7.16,9980,28.6,509,430
7.16,9990,28.7,509,430
7.17,9990,28.7,509,431
7.18,9990,28.7,509,431
7.19,9990,28.7,509,431
7.19,9990,28.8,509,432
7.2,9990,28.8,509,432
7.21,9990,28.8,509,433
7.22,9990,28.9,509,433
7.22,9990,28.9,509,434
7.23,9990,28.9,509,434
7.24,9990,29,509,434
7.25,9990,29,509,435
7.25,10000,29,509,435
7.26,10000,29,509,436
7.27,10000,29.1,509,436
7.27,10000,29.1,509,437
7.28,10000,29.1,509,437
7.29,10000,29.2,509,438
7.3,10000,29.2,509,438
7.3,10000,29.2,509,438
7.31,10000,29.2,509,439
7.32,10000,29.3,509,439
7.32,10000,29.3,509,440
7.33,10000,29.3,509,440
7.34,10000,29.4,509,441
7.35,10000,29.4,510,441
7.36,10010,29.4,510,441
7.36,10010,29.4,510,442
7.37,10010,29.5,510,442
7.38,10010,29.5,510,443
7.38,10010,29.5,510,443
7.39,10010,29.6,510,444
7.4,10010,29.6,510,444
7.41,10010,29.6,510,445
7.41,10010,29.7,510,445
7.42,10010,29.7,510,445
7.43,10010,29.7,510,446
7.44,10010,29.7,510,446
7.44,10010,29.8,510,447
7.45,10020,29.8,510,447
7.46,10020,29.8,510,448
7.46,10020,29.9,510,448
7.47,10020,29.9,510,448
7.48,10020,29.9,510,449
7.49,10020,29.9,510,449
7.49,10020,30,510,450
7.5,10020,30,510,450
7.51,10020,30,510,451
7.52,10020,30.1,510,451
7.52,10020,30.1,510,452
7.53,10020,30.1,510,452
7.54,10020,30.1,510,452
7.54,10020,30.2,510,453
7.55,10020,30.2,510,453
7.56,10020,30.2,510,454
7.57,10020,30.3,510,454
7.57,10020,30.3,510,455
7.58,10020,30.3,510,455
7.59,10020,30.4,511,455
7.6,10030,30.4,511,456
7.6,10030,30.4,511,456
7.61,10030,30.4,511,457
7.62,10030,30.5,511,457
7.62,10030,30.5,511,458
7.63,10030,30.5,511,458
7.64,10030,30.6,511,459
7.65,10030,30.6,511,459
7.65,10030,30.6,511,459
7.66,10030,30.6,511,460
7.67,10030,30.7,511,460
7.68,10030,30.7,511,461
7.68,10030,30.7,511,461
7.69,10030,30.8,511,462
7.7,10030,30.8,511,462
7.7,10030,30.8,511,462
7.71,10030,30.8,511,463
7.72,10030,30.9,511,463
7.73,10030,30.9,511,464
7.73,10030,30.9,511,464
7.74,10030,31,511,465
7.75,10040,31,511,465
7.76,10040,31,511,466
7.76,10030,31.1,511,466
7.77,10030,31.1,511,466
7.78,10030,31.1,511,467
7.78,10030,31.1,511,467
7.79,10040,31.2,511,468
7.8,10040,31.2,511,468
7.81,10040,31.2,511,469
7.81,10040,31.3,511,469
7.82,10030,31.3,511,469
7.83,10040,31.3,511,470
7.84,10040,31.3,511,470
7.84,10040,31.4,511,471
7.85,10040,31.4,511,471
7.86,10040,31.4,511,472
7.86,10040,31.5,511,472
7.87,10040,31.5,511,473
7.88,10040,31.5,511,473
7.89,10040,31.5,511,473
7.89,10040,31.6,511,474
7.9,10040,31.6,511,474
7.91,10040,31.6,511,475
7.92,10040,31.7,511,475
7.92,10040,31.7,511,476
7.93,10040,31.7,511,476
7.94,10040,31.8,511,476
7.94,10040,31.8,511,477
7.95,10040,31.8,511,477
7.96,10040,31.8,511,478
7.97,10040,31.9,511,478
7.98,10040,31.9,511,479
7.98,10040,31.9,511,479
7.99,10040,32,511,480
8,10040,32,511,480
8,10040,32,511,480
8.01,10040,32,511,481
8.02,10040,32.1,511,481
8.03,10040,32.1,511,482
8.03,10040,32.1,511,482
8.04,10040,32.2,511,483
8.05,10040,32.2,511,483
8.06,10040,32.2,511,483
8.06,10040,32.2,511,484
8.07,10040,32.3,511,484
8.08,10040,32.3,511,485
8.08,10040,32.3,511,485
8.09,10040,32.4,511,486
8.1,10040,32.4,511,486
8.11,10030,32.4,511,487
8.11,10030,32.5,511,487
8.12,10030,32.5,511,487
8.13,10030,32.5,511,488
8.14,10030,32.5,511,488
8.14,10030,32.6,511,489
8.15,10030,32.6,511,489
8.16,10030,32.6,511,490
8.16,10030,32.7,511,490
8.17,10030,32.7,511,490
8.18,10030,32.7,511,491
8.19,10030,32.7,511,491
8.19,10030,32.8,511,492
8.2,10030,32.8,511,492
8.21,10030,32.8,511,493
8.22,10020,32.9,511,493
8.22,10030,32.9,511,494
8.23,10030,32.9,511,494
8.24,10030,32.9,511,494
8.24,10020,33,511,495
8.25,10020,33,510,495
8.26,10020,33,510,496
8.27,10020,33.1,510,496
8.27,10020,33.1,510,497
8.28,10020,33.1,510,497
8.29,10020,33.2,510,497
8.3,10020,33.2,510,498
8.3,10020,33.2,510,498
8.31,10020,33.2,510,499
8.32,10020,33.3,510,499
8.32,10020,33.3,510,500
8.33,10010,33.3,510,500
8.34,10010,33.4,510,501
8.35,10010,33.4,510,501
8.35,10010,33.4,510,501
8.36,10010,33.4,510,502
8.37,10010,33.5,510,502
8.38,10010,33.5,510,503
8.38,10010,33.5,510,503
8.39,10000,33.6,509,504
8.4,10000,33.6,509,504
8.4,10000,33.6,509,504
8.41,10000,33.6,509,505
8.42,10000,33.7,509,505
8.43,10000,33.7,509,506
8.43,9990,33.7,509,506
8.44,9990,33.8,509,507
8.45,9990,33.8,509,507
8.46,9990,33.8,509,508
8.46,9990,33.9,509,508
8.47,9980,33.9,509,508
8.48,9980,33.9,508,509
8.48,9980,33.9,508,509
8.49,9980,34,508,510
8.5,9980,34,508,510
8.51,9970,34,508,511
8.51,9970,34.1,508,511
8.52,9970,34.1,508,511
8.53,9970,34.1,508,512
8.54,9960,34.1,508,512
8.54,9960,34.2,507,513
8.55,9960,34.2,507,513
8.56,9960,34.2,507,514
8.56,9960,34.3,507,514
8.57,9950,34.3,507,515
8.58,9950,34.3,507,515
8.59,9940,34.3,506,515
8.59,9940,34.4,506,516
8.6,9940,34.4,506,516
8.61,9940,34.4,506,517
8.62,9930,34.5,506,517
8.62,9930,34.5,506,518
8.63,9930,34.5,506,518
8.64,9920,34.6,505,518
8.64,9920,34.6,505,519
8.65,9920,34.6,505,519
8.66,9920,34.6,505,520
8.67,9910,34.7,505,520
8.68,9910,34.7,505,521
8.68,9900,34.7,504,521
8.69,9900,34.8,504,522
8.7,9900,34.8,504,522
8.7,9900,34.8,504,522
8.71,9890,34.8,504,523
8.72,9880,34.9,503,523
8.72,9880,34.9,503,524
8.73,9880,34.9,503,524
8.74,9870,35,503,525
8.75,9870,35,503,525
8.76,9860,35,502,525
8.76,9860,35,502,526
8.77,9860,35.1,502,526
8.78,9850,35.1,502,527
8.78,9840,35.1,501,527
8.79,9840,35.2,501,528
8.8,9840,35.2,501,528
8.81,9830,35.2,501,529
8.81,9830,35.3,500,529
8.82,9820,35.3,500,529
8.83,9820,35.3,500,530
8.84,9810,35.3,500,530
8.84,9800,35.4,499,531
8.85,9800,35.4,499,531
8.86,9800,35.4,499,532
8.86,9790,35.5,499,532
8.87,9790,35.5,498,532
8.88,9780,35.5,498,533
8.89,9770,35.5,498,533
8.89,9770,35.6,497,534
8.9,9760,35.6,497,534
8.91,9760,35.6,497,535
8.92,9750,35.7,497,535
8.92,9750,35.7,496,536
8.93,9740,35.7,496,536
8.94,9730,35.7,496,536
8.94,9730,35.8,495,537
8.95,9720,35.8,495,537
8.96,9720,35.8,495,538
8.97,9710,35.9,495,538
8.97,9700,35.9,494,539
8.98,9690,35.9,494,539
8.99,9690,36,493,539
9,9680,36,493,540
9,9680,36,493,540
9.01,9670,36,492,541
9.02,9660,36.1,492,541
9.02,9660,36.1,492,542
9.03,9650,36.1,491,542
9.04,9640,36.2,491,543
9.05,9630,36.2,491,543
9.05,9630,36.2,490,543
9.06,9620,36.2,490,544
9.07,9610,36.3,490,544
9.08,9600,36.3,489,545
9.08,9600,36.3,489,545
9.09,9590,36.4,488,546
9.1,9580,36.4,488,546
9.1,9580,36.4,488,546
9.11,9570,36.4,487,547
9.12,9560,36.5,487,547
9.13,9550,36.5,486,548
9.13,9540,36.5,486,548
9.14,9540,36.6,486,549
9.15,9530,36.6,485,549
9.16,9520,36.6,485,550
9.16,9510,36.7,484,550
9.17,9500,36.7,484,550
9.18,9490,36.7,483,551
9.18,9480,36.7,483,551
9.19,9480,36.8,483,552
9.2,9470,36.8,482,552
9.21,9460,36.8,482,553
9.21,9450,36.9,481,553
9.22,9440,36.9,481,553
9.23,9430,36.9,480,554
9.24,9420,36.9,480,554
9.24,9410,37,479,555
9.25,9400,37,479,555
9.26,9390,37,478,556
9.26,9380,37.1,478,556
9.27,9370,37.1,477,557
9.28,9360,37.1,477,557
9.29,9350,37.1,476,557
9.29,9340,37.2,476,558
9.3,9340,37.2,476,558
9.31,9330,37.2,475,559
9.32,9320,37.3,474,559
9.32,9300,37.3,474,560
9.33,9290,37.3,473,560
9.34,9280,37.4,473,560
9.34,9270,37.4,472,561
9.35,9260,37.4,472,561
9.36,9250,37.4,471,562
9.37,9240,37.5,471,562
9.38,9230,37.5,470,563
9.38,9220,37.5,469,563
9.39,9210,37.6,469,564
9.4,9200,37.6,468,564
9.4,9190,37.6,468,564
9.41,9180,37.6,467,565
9.42,9160,37.7,467,565
9.43,9150,37.7,466,566
9.43,9140,37.7,465,566
9.44,9130,37.8,465,567
9.45,9120,37.8,464,567
9.46,9110,37.8,464,567
9.46,9100,37.8,463,568
9.47,9080,37.9,462,568
9.48,9070,37.9,462,569
9.48,9060,37.9,461,569
9.49,9040,38,461,570
9.5,9030,38,460,570
9.51,9020,38,459,571
9.51,9000,38.1,459,571
9.52,8990,38.1,458,571
9.53,8980,38.1,457,572
9.54,8960,38.1,457,572
9.54,8950,38.2,456,573
9.55,8940,38.2,455,573
9.56,8930,38.2,455,574
9.56,8910,38.3,454,574
9.57,8900,38.3,453,574
9.58,8880,38.3,452,575
9.59,8870,38.3,452,575
9.59,8860,38.4,451,576
9.6,8840,38.4,450,576
9.61,8830,38.4,450,577
9.62,8810,38.5,449,577
9.62,8800,38.5,448,578
9.63,8780,38.5,447,578
9.64,8770,38.5,447,578
9.64,8760,38.6,446,579
9.65,8740,38.6,445,579
9.66,8720,38.6,444,580
9.67,8710,38.7,444,580
9.67,8690,38.7,443,581
9.68,8680,38.7,442,581
9.69,8660,38.8,441,581
9.7,8640,38.8,440,582
9.7,8630,38.8,440,582
9.71,8610,38.8,439,583
9.72,8600,38.9,438,583
9.72,8580,38.9,437,584
9.73,8560,38.9,436,584
9.74,8540,39,435,585
9.75,8530,39,434,585
9.75,8510,39,433,585
9.76,8490,39,433,586
9.77,8470,39.1,432,586
9.78,8460,39.1,431,587
9.78,8440,39.1,430,587
9.79,8420,39.2,429,588
9.8,8400,39.2,428,588
9.8,8380,39.2,427,588
9.81,8360,39.2,426,589
9.82,8340,39.3,425,589
9.83,8320,39.3,424,590
9.83,8300,39.3,423,590
9.84,8280,39.4,422,591
9.85,8260,39.4,421,591
9.86,8240,39.4,420,592
9.86,8220,39.5,419,592
9.87,8200,39.5,417,592
9.88,8170,39.5,416,593
9.88,8150,39.5,415,593
9.89,8130,39.6,414,594
9.9,8100,39.6,413,594
9.91,8070,39.6,411,595
9.91,8020,39.7,409,595
9.92,-943,39.7,-48,595
9.93,-943,39.7,-48,596
9.94,-943,39.7,-48,596
9.94,-943,39.8,-48,597
9.95,-942,39.8,-48,597
9.96,-940,39.8,-47.9,598
9.96,-942,39.9,-48,598
9.97,-940,39.9,-47.9,599
9.98,-942,39.9,-48,599
9.99,-940,39.9,-47.9,599
9.99,-940,40,-47.9,600
10,-940,40,-47.9,600
10.01,-940,40,-47.9,601
10.02,-938,40.1,-47.8,601
10.02,-940,40.1,-47.9,602
10.03,-938,40.1,-47.8,602
10.04,-938,40.2,-47.8,602
10.04,-938,40.2,-47.8,603
10.05,-938,40.2,-47.8,603
10.06,-938,40.2,-47.8,604
10.07,-938,40.3,-47.8,604
10.08,-938,40.3,-47.8,605
10.08,-938,40.3,-47.8,605
10.09,-938,40.4,-47.8,606
10.1,-937,40.4,-47.7,606
10.1,-938,40.4,-47.8,606
10.11,-937,40.4,-47.7,607
10.12,-937,40.5,-47.7,607
10.13,-938,40.5,-47.8,608
10.13,-937,40.5,-47.7,608
10.14,-938,40.6,-47.8,609
10.15,-937,40.6,-47.7,609
10.16,-938,40.6,-47.8,609
10.16,-937,40.6,-47.7,610
10.17,-937,40.7,-47.7,610
10.18,-938,40.7,-47.8,611
10.18,-938,40.7,-47.8,611
10.19,-937,40.8,-47.7,612
10.2,-937,40.8,-47.7,612
10.21,-937,40.8,-47.7,613
10.21,-937,40.9,-47.7,613
10.22,-937,40.9,-47.7,613
10.23,-937,40.9,-47.7,614
10.24,-937,40.9,-47.7,614
10.24,-937,41,-47.7,615
10.25,-937,41,-47.7,615
10.26,-937,41,-47.7,616
10.26,-937,41.1,-47.7,616
10.27,-937,41.1,-47.7,616
10.28,-937,41.1,-47.7,617
10.29,-937,41.1,-47.7,617
10.29,-937,41.2,-47.7,618
10.3,-937,41.2,-47.7,618
10.31,-937,41.2,-47.7,619
10.32,-937,41.3,-47.7,619
10.32,-937,41.3,-47.7,620
10.33,-937,41.3,-47.7,620
10.34,-937,41.3,-47.7,620
10.34,-937,41.4,-47.7,621
10.35,-937,41.4,-47.7,621
10.36,-937,41.4,-47.7,622
10.37,-937,41.5,-47.7,622
10.37,-937,41.5,-47.7,623
10.38,-937,41.5,-47.7,623
10.39,-937,41.6,-47.7,623
10.4,-937,41.6,-47.7,624
10.4,-937,41.6,-47.7,624
10.41,-937,41.6,-47.7,625
10.42,-937,41.7,-47.7,625
10.42,-937,41.7,-47.7,626
10.43,-937,41.7,-47.7,626
10.44,-937,41.8,-47.7,627
10.45,-937,41.8,-47.7,627
*****************************End of Data*****************************